Workbook

Sheet 使い方
A1: 厨房食数管理 入力用Excelテンプレート（試作版）
A3: ■ このファイルの役割
A4: このファイルに入力した内容を、管理者画面から「アップロード」すると、厨房タブレットの食数表に反映されます。
A5: 印刷は行いません。今まで通りの「欠食が出たら記入する」感覚で使えるよう設計しています。
A7: ■ シートの説明
A8: ・プレビュー 選んだ日付の厨房タブレット表示を簡易的に再現（GHの標準喫食ルールは含みません）
A9: ・月次集計 月初の食単価清算用。対象月の朝昼夕それぞれの合計食数を自動集計（GHの標準喫食ルールを含む正式な集計）
A10: ・食数記録 欠食者・臨時喫食者が出るたびに1行追加してください。
A11: ・職員食来客記録 職員食や来客が出た日だけ、日付と人数を1行追加してください。
A12: ・利用者名簿 新しく入所・退所した方がいたら、この表を更新してください。
A13: ・区分マスタ プルダウンの元データです。通常は触る必要はありません。
A15: ■ 入力のルール
... A23: 利用者名簿シートで該当欄に○をつけると、プレビュー画面の氏名の横に「(ダ)」のように自動で表示されます。

Sheet プレビュー
A1: 厨房タブレット 簡易プレビュー
A3: 表示する日付 | C3: 46247
A4: ※これは簡易プレビューです。「食数記録」シートに実際に入力された欠食・臨時喫食の登録内容のみを集計します。
A5: GH利用者の「平日昼は基本的に喫食」という標準ルールはここでは自動適用されません（本番のWebアプリ側の計算ロジックであり、このExcelプレビューには含まれません）。
B7: 朝食 | D7: 昼食 | F7: 夕食
A8: 男性入所 | B8: =COUNTIFS(利用者名簿!$B:$B,"男性入所",利用者名簿!$G:$G,"在籍")-COUNTIFS(食数記録!$A:$A,$C$3,食数記録!$B:$B,"朝",食数記録!$F:$F,"男性入所",食数記録!$D:$D,"欠食") -> 1 | D8: =COUNTIFS(利用者名簿!$B:$B,"男性入所",利用者名簿!$G:$G,"在籍")-COUNTIFS(食数記録!$A:$A,$C$3,食数記録!$B:$B,"昼",食数記録!$F:$F,"男性入所",食数記録!$D:$D,"欠食") -> 0 | F8: =COUNTIFS(利用者名簿!$B:$B,"男性入所",利用者名簿!$G:$G,"在籍")-COUNTIFS(食数記録!$A:$A,$C$3,食数記録!$B:$B,"夕",食数記録!$F:$F,"男性入所",食数記録!$D:$D,"欠食") -> 1
B9: =IFERROR(IF(INDEX(食数記録!$C:$C,MATCH(1,内部計算!$C:$C,0))="","",INDEX(食数記録!$C:$C,MATCH(1,内部計算!$C:$C,0))&IF(IFERROR(VLOOKUP(INDEX(食数記録!$C:$C,MATCH(1,内部計算!$C:$C,0)),利用者名簿!$A:$I,9,0),"")<>"","("&VLOOKUP(INDEX(食数記録!$C:$C,MATCH(1,内部計算!$C:$C,0)),利用者名簿!$A:$I,9,0)&")","")),"") | D9: =IFERROR(IF(INDEX(食数記録!$C:$C,MATCH(1,内部計算!$E:$E,0))="","",INDEX(食数記録!$C:$C,MATCH(1,内部計算!$E:$E,0))&IF(IFERROR(VLOOKUP(INDEX(食数記録!$C:$C,MATCH(1,内部計算!$E:$E,0)),利用者名簿!$A:$I,9,0),"")<>"","("&VLOOKUP(INDEX(食数記録!$C:$C,MATCH(1,内部計算!$E:$E,0)),利用者名簿!$A:$I,9,0)&")","")),"") -> 山田 太郎 | F9: =IFERROR(IF(INDEX(食数記録!$C:$C,MATCH(1,内部計算!$G:$G,0))="","",INDEX(食数記録!$C:$C,MATCH(1,内部計算!$G:$G,0))&IF(IFERROR(VLOOKUP(INDEX(食数記録!$C:$C,MATCH(1,内部計算!$G:$G,0)),利用者名簿!$A:$I,9,0),"")<>"","("&VLOOKUP(INDEX(食数記録!$C:$C,MATCH(1,内部計算!$G:$G,0)),利用者名簿!$A:$I,9,0)&")","")),"")
B10: =IFERROR(IF(INDEX(食数記録!$C:$C,MATCH(2,内部計算!$C:$C,0))="","",INDEX(食数記録!$C:$C,MATCH(2,内部計算!$C:$C,0))&IF(IFERROR(VLOOKUP(INDEX(食数記録!$C:$C,MATCH(2,内部計算!$C:$C,0)),利用者名簿!$A:$I,9,0),"")<>"","("&VLOOKUP(INDEX(食数記録!$C:$C,MATCH(2,内部計算!$C:$C,0)),利用者名簿!$A:$I,9,0)&")","")),"") | D10: =IFERROR(IF(INDEX(食数記録!$C:$C,MATCH(2,内部計算!$E:$E,0))="","",INDEX(食数記録!$C:$C,MATCH(2,内部計算!$E:$E,0))&IF(IFERROR(VLOOKUP(INDEX(食数記録!$C:$C,MATCH(2,内部計算!$E:$E,0)),利用者名簿!$A:$I,9,0),"")<>"","("&VLOOKUP(INDEX(食数記録!$C:$C,MATCH(2,内部計算!$E:$E,0)),利用者名簿!$A:$I,9,0)&")","")),"") | F10: =IFERROR(IF(INDEX(食数記録!$C:$C,MATCH(2,内部計算!$G:$G,0))="","",INDEX(食数記録!$C:$C,MATCH(2,内部計算!$G:$G,0))&IF(IFERROR(VLOOKUP(INDEX(食数記録!$C:$C,MATCH(2,内部計算!$G:$G,0)),利用者名簿!$A:$I,9,0),"")<>"","("&VLOOKUP(INDEX(食数記録!$C:$C,MATCH(2,内部計算!$G:$G,0)),利用者名簿!$A:$I,9,0)&")","")),"")
B11: =IFERROR(IF(INDEX(食数記録!$C:$C,MATCH(3,内部計算!$C:$C,0))="","",INDEX(食数記録!$C:$C,MATCH(3,内部計算!$C:$C,0))&IF(IFERROR(VLOOKUP(INDEX(食数記録!$C:$C,MATCH(3,内部計算!$C:$C,0)),利用者名簿!$A:$I,9,0),"")<>"","("&VLOOKUP(INDEX(食数記録!$C:$C,MATCH(3,内部計算!$C:$C,0)),利用者名簿!$A:$I,9,0)&")","")),"") | D11: =IFERROR(IF(INDEX(食数記録!$C:$C,MATCH(3,内部計算!$E:$E,0))="","",INDEX(食数記録!$C:$C,MATCH(3,内部計算!$E:$E,0))&IF(IFERROR(VLOOKUP(INDEX(食数記録!$C:$C,MATCH(3,内部計算!$E:$E,0)),利用者名簿!$A:$I,9,0),"")<>"","("&VLOOKUP(INDEX(食数記録!$C:$C,MATCH(3,内部計算!$E:$E,0)),利用者名簿!$A:$I,9,0)&")","")),"") | F11: =IFERROR(IF(INDEX(食数記録!$C:$C,MATCH(3,内部計算!$G:$G,0))="","",INDEX(食数記録!$C:$C,MATCH(3,内部計算!$G:$G,0))&IF(IFERROR(VLOOKUP(INDEX(食数記録!$C:$C,MATCH(3,内部計算!$G:$G,0)),利用者名簿!$A:$I,9,0),"")<>"","("&VLOOKUP(INDEX(食数記録!$C:$C,MATCH(3,内部計算!$G:$G,0)),利用者名簿!$A:$I,9,0)&")","")),"")
B12: =IFERROR(IF(INDEX(食数記録!$C:$C,MATCH(4,内部計算!$C:$C,0))="","",INDEX(食数記録!$C:$C,MATCH(4,内部計算!$C:$C,0))&IF(IFERROR(VLOOKUP(INDEX(食数記録!$C:$C,MATCH(4,内部計算!$C:$C,0)),利用者名簿!$A:$I,9,0),"")<>"","("&VLOOKUP(INDEX(食数記録!$C:$C,MATCH(4,内部計算!$C:$C,0)),利用者名簿!$A:$I,9,0)&")","")),"") | D12: =IFERROR(IF(INDEX(食数記録!$C:$C,MATCH(4,内部計算!$E:$E,0))="","",INDEX(食数記録!$C:$C,MATCH(4,内部計算!$E:$E,0))&IF(IFERROR(VLOOKUP(INDEX(食数記録!$C:$C,MATCH(4,内部計算!$E:$E,0)),利用者名簿!$A:$I,9,0),"")<>"","("&VLOOKUP(INDEX(食数記録!$C:$C,MATCH(4,内部計算!$E:$E,0)),利用者名簿!$A:$I,9,0)&")","")),"") | F12: =IFERROR(IF(INDEX(食数記録!$C:$C,MATCH(4,内部計算!$G:$G,0))="","",INDEX(食数記録!$C:$C,MATCH(4,内部計算!$G:$G,0))&IF(IFERROR(VLOOKUP(INDEX(食数記録!$C:$C,MATCH(4,内部計算!$G:$G,0)),利用者名簿!$A:$I,9,0),"")<>"","("&VLOOKUP(INDEX(食数記録!$C:$C,MATCH(4,内部計算!$G:$G,0)),利用者名簿!$A:$I,9,0)&")","")),"")
B13: =IFERROR(IF(INDEX(食数記録!$C:$C,MATCH(5,内部計算!$C:$C,0))="","",INDEX(食数記録!$C:$C,MATCH(5,内部計算!$C:$C,0))&IF(IFERROR(VLOOKUP(INDEX(食数記録!$C:$C,MATCH(5,内部計算!$C:$C,0)),利用者名簿!$A:$I,9,0),"")<>"","("&VLOOKUP(INDEX(食数記録!$C:$C,MATCH(5,内部計算!$C:$C,0)),利用者名簿!$A:$I,9,0)&")","")),"") | D13: =IFERROR(IF(INDEX(食数記録!$C:$C,MATCH(5,内部計算!$E:$E,0))="","",INDEX(食数記録!$C:$C,MATCH(5,内部計算!$E:$E,0))&IF(IFERROR(VLOOKUP(INDEX(食数記録!$C:$C,MATCH(5,内部計算!$E:$E,0)),利用者名簿!$A:$I,9,0),"")<>"","("&VLOOKUP(INDEX(食数記録!$C:$C,MATCH(5,内部計算!$E:$E,0)),利用者名簿!$A:$I,9,0)&")","")),"") | F13: =IFERROR(IF(INDEX(食数記録!$C:$C,MATCH(5,内部計算!$G:$G,0))="","",INDEX(食数記録!$C:$C,MATCH(5,内部計算!$G:$G,0))&IF(IFERROR(VLOOKUP(INDEX(食数記録!$C:$C,MATCH(5,内部計算!$G:$G,0)),利用者名簿!$A:$I,9,0),"")<>"","("&VLOOKUP(INDEX(食数記録!$C:$C,MATCH(5,内部計算!$G:$G,0)),利用者名簿!$A:$I,9,0)&")","")),"")
B14: =IFERROR(IF(INDEX(食数記録!$C:$C,MATCH(6,内部計算!$C:$C,0))="","",INDEX(食数記録!$C:$C,MATCH(6,内部計算!$C:$C,0))&IF(IFERROR(VLOOKUP(INDEX(食数記録!$C:$C,MATCH(6,内部計算!$C:$C,0)),利用者名簿!$A:$I,9,0),"")<>"","("&VLOOKUP(INDEX(食数記録!$C:$C,MATCH(6,内部計算!$C:$C,0)),利用者名簿!$A:$I,9,0)&")","")),"") | D14: =IFERROR(IF(INDEX(食数記録!$C:$C,MATCH(6,内部計算!$E:$E,0))="","",INDEX(食数記録!$C:$C,MATCH(6,内部計算!$E:$E,0))&IF(IFERROR(VLOOKUP(INDEX(食数記録!$C:$C,MATCH(6,内部計算!$E:$E,0)),利用者名簿!$A:$I,9,0),"")<>"","("&VLOOKUP(INDEX(食数記録!$C:$C,MATCH(6,内部計算!$E:$E,0)),利用者名簿!$A:$I,9,0)&")","")),"") | F14: =IFERROR(IF(INDEX(食数記録!$C:$C,MATCH(6,内部計算!$G:$G,0))="","",INDEX(食数記録!$C:$C,MATCH(6,内部計算!$G:$G,0))&IF(IFERROR(VLOOKUP(INDEX(食数記録!$C:$C,MATCH(6,内部計算!$G:$G,0)),利用者名簿!$A:$I,9,0),"")<>"","("&VLOOKUP(INDEX(食数記録!$C:$C,MATCH(6,内部計算!$G:$G,0)),利用者名簿!$A:$I,9,0)&")","")),"")
B15: =IFERROR(IF(INDEX(食数記録!$C:$C,MATCH(7,内部計算!$C:$C,0))="","",INDEX(食数記録!$C:$C,MATCH(7,内部計算!$C:$C,0))&IF(IFERROR(VLOOKUP(INDEX(食数記録!$C:$C,MATCH(7,内部計算!$C:$C,0)),利用者名簿!$A:$I,9,0),"")<>"","("&VLOOKUP(INDEX(食数記録!$C:$C,MATCH(7,内部計算!$C:$C,0)),利用者名簿!$A:$I,9,0)&")","")),"") | D15: =IFERROR(IF(INDEX(食数記録!$C:$C,MATCH(7,内部計算!$E:$E,0))="","",INDEX(食数記録!$C:$C,MATCH(7,内部計算!$E:$E,0))&IF(IFERROR(VLOOKUP(INDEX(食数記録!$C:$C,MATCH(7,内部計算!$E:$E,0)),利用者名簿!$A:$I,9,0),"")<>"","("&VLOOKUP(INDEX(食数記録!$C:$C,MATCH(7,内部計算!$E:$E,0)),利用者名簿!$A:$I,9,0)&")","")),"") | F15: =IFERROR(IF(INDEX(食数記録!$C:$C,MATCH(7,内部計算!$G:$G,0))="","",INDEX(食数記録!$C:$C,MATCH(7,内部計算!$G:$G,0))&IF(IFERROR(VLOOKUP(INDEX(食数記録!$C:$C,MATCH(7,内部計算!$G:$G,0)),利用者名簿!$A:$I,9,0),"")<>"","("&VLOOKUP(INDEX(食数記録!$C:$C,MATCH(7,内部計算!$G:$G,0)),利用者名簿!$A:$I,9,0)&")","")),"")
B16: =IFERROR(IF(INDEX(食数記録!$C:$C,MATCH(8,内部計算!$C:$C,0))="","",INDEX(食数記録!$C:$C,MATCH(8,内部計算!$C:$C,0))&IF(IFERROR(VLOOKUP(INDEX(食数記録!$C:$C,MATCH(8,内部計算!$C:$C,0)),利用者名簿!$A:$I,9,0),"")<>"","("&VLOOKUP(INDEX(食数記録!$C:$C,MATCH(8,内部計算!$C:$C,0)),利用者名簿!$A:$I,9,0)&")","")),"") | D16: =IFERROR(IF(INDEX(食数記録!$C:$C,MATCH(8,内部計算!$E:$E,0))="","",INDEX(食数記録!$C:$C,MATCH(8,内部計算!$E:$E,0))&IF(IFERROR(VLOOKUP(INDEX(食数記録!$C:$C,MATCH(8,内部計算!$E:$E,0)),利用者名簿!$A:$I,9,0),"")<>"","("&VLOOKUP(INDEX(食数記録!$C:$C,MATCH(8,内部計算!$E:$E,0)),利用者名簿!$A:$I,9,0)&")","")),"") | F16: =IFERROR(IF(INDEX(食数記録!$C:$C,MATCH(8,内部計算!$G:$G,0))="","",INDEX(食数記録!$C:$C,MATCH(8,内部計算!$G:$G,0))&IF(IFERROR(VLOOKUP(INDEX(食数記録!$C:$C,MATCH(8,内部計算!$G:$G,0)),利用者名簿!$A:$I,9,0),"")<>"","("&VLOOKUP(INDEX(食数記録!$C:$C,MATCH(8,内部計算!$G:$G,0)),利用者名簿!$A:$I,9,0)&")","")),"")
A17: 女性入所 | B17: =COUNTIFS(利用者名簿!$B:$B,"女性入所",利用者名簿!$G:$G,"在籍")-COUNTIFS(食数記録!$A:$A,$C$3,食数記録!$B:$B,"朝",食数記録!$F:$F,"女性入所",食数記録!$D:$D,"欠食") -> 0 | D17: =COUNTIFS(利用者名簿!$B:$B,"女性入所",利用者名簿!$G:$G,"在籍")-COUNTIFS(食数記録!$A:$A,$C$3,食数記録!$B:$B,"昼",食数記録!$F:$F,"女性入所",食数記録!$D:$D,"欠食") -> 1 | F17: =COUNTIFS(利用者名簿!$B:$B,"女性入所",利用者名簿!$G:$G,"在籍")-COUNTIFS(食数記録!$A:$A,$C$3,食数記録!$B:$B,"夕",食数記録!$F:$F,"女性入所",食数記録!$D:$D,"欠食") -> 1
B18: =IFERROR(IF(INDEX(食数記録!$C:$C,MATCH(1,内部計算!$I:$I,0))="","",INDEX(食数記録!$C:$C,MATCH(1,内部計算!$I:$I,0))&IF(IFERROR(VLOOKUP(INDEX(食数記録!$C:$C,MATCH(1,内部計算!$I:$I,0)),利用者名簿!$A:$I,9,0),"")<>"","("&VLOOKUP(INDEX(食数記録!$C:$C,MATCH(1,内部計算!$I:$I,0)),利用者名簿!$A:$I,9,0)&")","")),"") -> 鈴木 花子(キ) | D18: =IFERROR(IF(INDEX(食数記録!$C:$C,MATCH(1,内部計算!$K:$K,0))="","",INDEX(食数記録!$C:$C,MATCH(1,内部計算!$K:$K,0))&IF(IFERROR(VLOOKUP(INDEX(食数記録!$C:$C,MATCH(1,内部計算!$K:$K,0)),利用者名簿!$A:$I,9,0),"")<>"","("&VLOOKUP(INDEX(食数記録!$C:$C,MATCH(1,内部計算!$K:$K,0)),利用者名簿!$A:$I,9,0)&")","")),"") | F18: =IFERROR(IF(INDEX(食数記録!$C:$C,MATCH(1,内部計算!$M:$M,0))="","",INDEX(食数記録!$C:$C,MATCH(1,内部計算!$M:$M,0))&IF(IFERROR(VLOOKUP(INDEX(食数記録!$C:$C,MATCH(1,内部計算!$M:$M,0)),利用者名簿!$A:$I,9,0),"")<>"","("&VLOOKUP(INDEX(食数記録!$C:$C,MATCH(1,内部計算!$M:$M,0)),利用者名簿!$A:$I,9,0)&")","")),"")
B19: =IFERROR(IF(INDEX(食数記録!$C:$C,MATCH(2,内部計算!$I:$I,0))="","",INDEX(食数記録!$C:$C,MATCH(2,内部計算!$I:$I,0))&IF(IFERROR(VLOOKUP(INDEX(食数記録!$C:$C,MATCH(2,内部計算!$I:$I,0)),利用者名簿!$A:$I,9,0),"")<>"","("&VLOOKUP(INDEX(食数記録!$C:$C,MATCH(2,内部計算!$I:$I,0)),利用者名簿!$A:$I,9,0)&")","")),"") | D19: =IFERROR(IF(INDEX(食数記録!$C:$C,MATCH(2,内部計算!$K:$K,0))="","",INDEX(食数記録!$C:$C,MATCH(2,内部計算!$K:$K,0))&IF(IFERROR(VLOOKUP(INDEX(食数記録!$C:$C,MATCH(2,内部計算!$K:$K,0)),利用者名簿!$A:$I,9,0),"")<>"","("&VLOOKUP(INDEX(食数記録!$C:$C,MATCH(2,内部計算!$K:$K,0)),利用者名簿!$A:$I,9,0)&")","")),"") | F19: =IFERROR(IF(INDEX(食数記録!$C:$C,MATCH(2,内部計算!$M:$M,0))="","",INDEX(食数記録!$C:$C,MATCH(2,内部計算!$M:$M,0))&IF(IFERROR(VLOOKUP(INDEX(食数記録!$C:$C,MATCH(2,内部計算!$M:$M,0)),利用者名簿!$A:$I,9,0),"")<>"","("&VLOOKUP(INDEX(食数記録!$C:$C,MATCH(2,内部計算!$M:$M,0)),利用者名簿!$A:$I,9,0)&")","")),"")
B20: =IFERROR(IF(INDEX(食数記録!$C:$C,MATCH(3,内部計算!$I:$I,0))="","",INDEX(食数記録!$C:$C,MATCH(3,内部計算!$I:$I,0))&IF(IFERROR(VLOOKUP(INDEX(食数記録!$C:$C,MATCH(3,内部計算!$I:$I,0)),利用者名簿!$A:$I,9,0),"")<>"","("&VLOOKUP(INDEX(食数記録!$C:$C,MATCH(3,内部計算!$I:$I,0)),利用者名簿!$A:$I,9,0)&")","")),"") | D20: =IFERROR(IF(INDEX(食数記録!$C:$C,MATCH(3,内部計算!$K:$K,0))="","",INDEX(食数記録!$C:$C,MATCH(3,内部計算!$K:$K,0))&IF(IFERROR(VLOOKUP(INDEX(食数記録!$C:$C,MATCH(3,内部計算!$K:$K,0)),利用者名簿!$A:$I,9,0),"")<>"","("&VLOOKUP(INDEX(食数記録!$C:$C,MATCH(3,内部計算!$K:$K,0)),利用者名簿!$A:$I,9,0)&")","")),"") | F20: =IFERROR(IF(INDEX(食数記録!$C:$C,MATCH(3,内部計算!$M:$M,0))="","",INDEX(食数記録!$C:$C,MATCH(3,内部計算!$M:$M,0))&IF(IFERROR(VLOOKUP(INDEX(食数記録!$C:$C,MATCH(3,内部計算!$M:$M,0)),利用者名簿!$A:$I,9,0),"")<>"","("&VLOOKUP(INDEX(食数記録!$C:$C,MATCH(3,内部計算!$M:$M,0)),利用者名簿!$A:$I,9,0)&")","")),"")
B21: =IFERROR(IF(INDEX(食数記録!$C:$C,MATCH(4,内部計算!$I:$I,0))="","",INDEX(食数記録!$C:$C,MATCH(4,内部計算!$I:$I,0))&IF(IFERROR(VLOOKUP(INDEX(食数記録!$C:$C,MATCH(4,内部計算!$I:$I,0)),利用者名簿!$A:$I,9,0),"")<>"","("&VLOOKUP(INDEX(食数記録!$C:$C,MATCH(4,内部計算!$I:$I,0)),利用者名簿!$A:$I,9,0)&")","")),"") | D21: =IFERROR(IF(INDEX(食数記録!$C:$C,MATCH(4,内部計算!$K:$K,0))="","",INDEX(食数記録!$C:$C,MATCH(4,内部計算!$K:$K,0))&IF(IFERROR(VLOOKUP(INDEX(食数記録!$C:$C,MATCH(4,内部計算!$K:$K,0)),利用者名簿!$A:$I,9,0),"")<>"","("&VLOOKUP(INDEX(食数記録!$C:$C,MATCH(4,内部計算!$K:$K,0)),利用者名簿!$A:$I,9,0)&")","")),"") | F21: =IFERROR(IF(INDEX(食数記録!$C:$C,MATCH(4,内部計算!$M:$M,0))="","",INDEX(食数記録!$C:$C,MATCH(4,内部計算!$M:$M,0))&IF(IFERROR(VLOOKUP(INDEX(食数記録!$C:$C,MATCH(4,内部計算!$M:$M,0)),利用者名簿!$A:$I,9,0),"")<>"","("&VLOOKUP(INDEX(食数記録!$C:$C,MATCH(4,内部計算!$M:$M,0)),利用者名簿!$A:$I,9,0)&")","")),"")
B22: =IFERROR(IF(INDEX(食数記録!$C:$C,MATCH(5,内部計算!$I:$I,0))="","",INDEX(食数記録!$C:$C,MATCH(5,内部計算!$I:$I,0))&IF(IFERROR(VLOOKUP(INDEX(食数記録!$C:$C,MATCH(5,内部計算!$I:$I,0)),利用者名簿!$A:$I,9,0),"")<>"","("&VLOOKUP(INDEX(食数記録!$C:$C,MATCH(5,内部計算!$I:$I,0)),利用者名簿!$A:$I,9,0)&")","")),"") | D22: =IFERROR(IF(INDEX(食数記録!$C:$C,MATCH(5,内部計算!$K:$K,0))="","",INDEX(食数記録!$C:$C,MATCH(5,内部計算!$K:$K,0))&IF(IFERROR(VLOOKUP(INDEX(食数記録!$C:$C,MATCH(5,内部計算!$K:$K,0)),利用者名簿!$A:$I,9,0),"")<>"","("&VLOOKUP(INDEX(食数記録!$C:$C,MATCH(5,内部計算!$K:$K,0)),利用者名簿!$A:$I,9,0)&")","")),"") | F22: =IFERROR(IF(INDEX(食数記録!$C:$C,MATCH(5,内部計算!$M:$M,0))="","",INDEX(食数記録!$C:$C,MATCH(5,内部計算!$M:$M,0))&IF(IFERROR(VLOOKUP(INDEX(食数記録!$C:$C,MATCH(5,内部計算!$M:$M,0)),利用者名簿!$A:$I,9,0),"")<>"","("&VLOOKUP(INDEX(食数記録!$C:$C,MATCH(5,内部計算!$M:$M,0)),利用者名簿!$A:$I,9,0)&")","")),"")
B23: =IFERROR(IF(INDEX(食数記録!$C:$C,MATCH(6,内部計算!$I:$I,0))="","",INDEX(食数記録!$C:$C,MATCH(6,内部計算!$I:$I,0))&IF(IFERROR(VLOOKUP(INDEX(食数記録!$C:$C,MATCH(6,内部計算!$I:$I,0)),利用者名簿!$A:$I,9,0),"")<>"","("&VLOOKUP(INDEX(食数記録!$C:$C,MATCH(6,内部計算!$I:$I,0)),利用者名簿!$A:$I,9,0)&")","")),"") | D23: =IFERROR(IF(INDEX(食数記録!$C:$C,MATCH(6,内部計算!$K:$K,0))="","",INDEX(食数記録!$C:$C,MATCH(6,内部計算!$K:$K,0))&IF(IFERROR(VLOOKUP(INDEX(食数記録!$C:$C,MATCH(6,内部計算!$K:$K,0)),利用者名簿!$A:$I,9,0),"")<>"","("&VLOOKUP(INDEX(食数記録!$C:$C,MATCH(6,内部計算!$K:$K,0)),利用者名簿!$A:$I,9,0)&")","")),"") | F23: =IFERROR(IF(INDEX(食数記録!$C:$C,MATCH(6,内部計算!$M:$M,0))="","",INDEX(食数記録!$C:$C,MATCH(6,内部計算!$M:$M,0))&IF(IFERROR(VLOOKUP(INDEX(食数記録!$C:$C,MATCH(6,内部計算!$M:$M,0)),利用者名簿!$A:$I,9,0),"")<>"","("&VLOOKUP(INDEX(食数記録!$C:$C,MATCH(6,内部計算!$M:$M,0)),利用者名簿!$A:$I,9,0)&")","")),"")
B24: =IFERROR(IF(INDEX(食数記録!$C:$C,MATCH(7,内部計算!$I:$I,0))="","",INDEX(食数記録!$C:$C,MATCH(7,内部計算!$I:$I,0))&IF(IFERROR(VLOOKUP(INDEX(食数記録!$C:$C,MATCH(7,内部計算!$I:$I,0)),利用者名簿!$A:$I,9,0),"")<>"","("&VLOOKUP(INDEX(食数記録!$C:$C,MATCH(7,内部計算!$I:$I,0)),利用者名簿!$A:$I,9,0)&")","")),"") | D24: =IFERROR(IF(INDEX(食数記録!$C:$C,MATCH(7,内部計算!$K:$K,0))="","",INDEX(食数記録!$C:$C,MATCH(7,内部計算!$K:$K,0))&IF(IFERROR(VLOOKUP(INDEX(食数記録!$C:$C,MATCH(7,内部計算!$K:$K,0)),利用者名簿!$A:$I,9,0),"")<>"","("&VLOOKUP(INDEX(食数記録!$C:$C,MATCH(7,内部計算!$K:$K,0)),利用者名簿!$A:$I,9,0)&")","")),"") | F24: =IFERROR(IF(INDEX(食数記録!$C:$C,MATCH(7,内部計算!$M:$M,0))="","",INDEX(食数記録!$C:$C,MATCH(7,内部計算!$M:$M,0))&IF(IFERROR(VLOOKUP(INDEX(食数記録!$C:$C,MATCH(7,内部計算!$M:$M,0)),利用者名簿!$A:$I,9,0),"")<>"","("&VLOOKUP(INDEX(食数記録!$C:$C,MATCH(7,内部計算!$M:$M,0)),利用者名簿!$A:$I,9,0)&")","")),"")
B25: =IFERROR(IF(INDEX(食数記録!$C:$C,MATCH(8,内部計算!$I:$I,0))="","",INDEX(食数記録!$C:$C,MATCH(8,内部計算!$I:$I,0))&IF(IFERROR(VLOOKUP(INDEX(食数記録!$C:$C,MATCH(8,内部計算!$I:$I,0)),利用者名簿!$A:$I,9,0),"")<>"","("&VLOOKUP(INDEX(食数記録!$C:$C,MATCH(8,内部計算!$I:$I,0)),利用者名簿!$A:$I,9,0)&")","")),"") | D25: =IFERROR(IF(INDEX(食数記録!$C:$C,MATCH(8,内部計算!$K:$K,0))="","",INDEX(食数記録!$C:$C,MATCH(8,内部計算!$K:$K,0))&IF(IFERROR(VLOOKUP(INDEX(食数記録!$C:$C,MATCH(8,内部計算!$K:$K,0)),利用者名簿!$A:$I,9,0),"")<>"","("&VLOOKUP(INDEX(食数記録!$C:$C,MATCH(8,内部計算!$K:$K,0)),利用者名簿!$A:$I,9,0)&")","")),"") | F25: =IFERROR(IF(INDEX(食数記録!$C:$C,MATCH(8,内部計算!$M:$M,0))="","",INDEX(食数記録!$C:$C,MATCH(8,内部計算!$M:$M,0))&IF(IFERROR(VLOOKUP(INDEX(食数記録!$C:$C,MATCH(8,内部計算!$M:$M,0)),利用者名簿!$A:$I,9,0),"")<>"","("&VLOOKUP(INDEX(食数記録!$C:$C,MATCH(8,内部計算!$M:$M,0)),利用者名簿!$A:$I,9,0)&")","")),"")
A26: 男性GH | B26: =COUNTIFS(食数記録!$A:$A,$C$3,食数記録!$B:$B,"朝",食数記録!$F:$F,"男性GH",食数記録!$D:$D,"臨時喫食") -> 0 | D26: =COUNTIFS(食数記録!$A:$A,$C$3,食数記録!$B:$B,"昼",食数記録!$F:$F,"男性GH",食数記録!$D:$D,"臨時喫食") -> 0 | F26: =COUNTIFS(食数記録!$A:$A,$C$3,食数記録!$B:$B,"夕",食数記録!$F:$F,"男性GH",食数記録!$D:$D,"臨時喫食") -> 0
B27: =IFERROR(IF(INDEX(食数記録!$C:$C,MATCH(1,内部計算!$O:$O,0))="","",INDEX(食数記録!$C:$C,MATCH(1,内部計算!$O:$O,0))&IF(IFERROR(VLOOKUP(INDEX(食数記録!$C:$C,MATCH(1,内部計算!$O:$O,0)),利用者名簿!$A:$I,9,0),"")<>"","("&VLOOKUP(INDEX(食数記録!$C:$C,MATCH(1,内部計算!$O:$O,0)),利用者名簿!$A:$I,9,0)&")","")),"") | D27: =IFERROR(IF(INDEX(食数記録!$C:$C,MATCH(1,内部計算!$Q:$Q,0))="","",INDEX(食数記録!$C:$C,MATCH(1,内部計算!$Q:$Q,0))&IF(IFERROR(VLOOKUP(INDEX(食数記録!$C:$C,MATCH(1,内部計算!$Q:$Q,0)),利用者名簿!$A:$I,9,0),"")<>"","("&VLOOKUP(INDEX(食数記録!$C:$C,MATCH(1,内部計算!$Q:$Q,0)),利用者名簿!$A:$I,9,0)&")","")),"") | F27: =IFERROR(IF(INDEX(食数記録!$C:$C,MATCH(1,内部計算!$S:$S,0))="","",INDEX(食数記録!$C:$C,MATCH(1,内部計算!$S:$S,0))&IF(IFERROR(VLOOKUP(INDEX(食数記録!$C:$C,MATCH(1,内部計算!$S:$S,0)),利用者名簿!$A:$I,9,0),"")<>"","("&VLOOKUP(INDEX(食数記録!$C:$C,MATCH(1,内部計算!$S:$S,0)),利用者名簿!$A:$I,9,0)&")","")),"")
B28: =IFERROR(IF(INDEX(食数記録!$C:$C,MATCH(2,内部計算!$O:$O,0))="","",INDEX(食数記録!$C:$C,MATCH(2,内部計算!$O:$O,0))&IF(IFERROR(VLOOKUP(INDEX(食数記録!$C:$C,MATCH(2,内部計算!$O:$O,0)),利用者名簿!$A:$I,9,0),"")<>"","("&VLOOKUP(INDEX(食数記録!$C:$C,MATCH(2,内部計算!$O:$O,0)),利用者名簿!$A:$I,9,0)&")","")),"") | D28: =IFERROR(IF(INDEX(食数記録!$C:$C,MATCH(2,内部計算!$Q:$Q,0))="","",INDEX(食数記録!$C:$C,MATCH(2,内部計算!$Q:$Q,0))&IF(IFERROR(VLOOKUP(INDEX(食数記録!$C:$C,MATCH(2,内部計算!$Q:$Q,0)),利用者名簿!$A:$I,9,0),"")<>"","("&VLOOKUP(INDEX(食数記録!$C:$C,MATCH(2,内部計算!$Q:$Q,0)),利用者名簿!$A:$I,9,0)&")","")),"") | F28: =IFERROR(IF(INDEX(食数記録!$C:$C,MATCH(2,内部計算!$S:$S,0))="","",INDEX(食数記録!$C:$C,MATCH(2,内部計算!$S:$S,0))&IF(IFERROR(VLOOKUP(INDEX(食数記録!$C:$C,MATCH(2,内部計算!$S:$S,0)),利用者名簿!$A:$I,9,0),"")<>"","("&VLOOKUP(INDEX(食数記録!$C:$C,MATCH(2,内部計算!$S:$S,0)),利用者名簿!$A:$I,9,0)&")","")),"")
B29: =IFERROR(IF(INDEX(食数記録!$C:$C,MATCH(3,内部計算!$O:$O,0))="","",INDEX(食数記録!$C:$C,MATCH(3,内部計算!$O:$O,0))&IF(IFERROR(VLOOKUP(INDEX(食数記録!$C:$C,MATCH(3,内部計算!$O:$O,0)),利用者名簿!$A:$I,9,0),"")<>"","("&VLOOKUP(INDEX(食数記録!$C:$C,MATCH(3,内部計算!$O:$O,0)),利用者名簿!$A:$I,9,0)&")","")),"") | D29: =IFERROR(IF(INDEX(食数記録!$C:$C,MATCH(3,内部計算!$Q:$Q,0))="","",INDEX(食数記録!$C:$C,MATCH(3,内部計算!$Q:$Q,0))&IF(IFERROR(VLOOKUP(INDEX(食数記録!$C:$C,MATCH(3,内部計算!$Q:$Q,0)),利用者名簿!$A:$I,9,0),"")<>"","("&VLOOKUP(INDEX(食数記録!$C:$C,MATCH(3,内部計算!$Q:$Q,0)),利用者名簿!$A:$I,9,0)&")","")),"") | F29: =IFERROR(IF(INDEX(食数記録!$C:$C,MATCH(3,内部計算!$S:$S,0))="","",INDEX(食数記録!$C:$C,MATCH(3,内部計算!$S:$S,0))&IF(IFERROR(VLOOKUP(INDEX(食数記録!$C:$C,MATCH(3,内部計算!$S:$S,0)),利用者名簿!$A:$I,9,0),"")<>"","("&VLOOKUP(INDEX(食数記録!$C:$C,MATCH(3,内部計算!$S:$S,0)),利用者名簿!$A:$I,9,0)&")","")),"")
B30: =IFERROR(IF(INDEX(食数記録!$C:$C,MATCH(4,内部計算!$O:$O,0))="","",INDEX(食数記録!$C:$C,MATCH(4,内部計算!$O:$O,0))&IF(IFERROR(VLOOKUP(INDEX(食数記録!$C:$C,MATCH(4,内部計算!$O:$O,0)),利用者名簿!$A:$I,9,0),"")<>"","("&VLOOKUP(INDEX(食数記録!$C:$C,MATCH(4,内部計算!$O:$O,0)),利用者名簿!$A:$I,9,0)&")","")),"") | D30: =IFERROR(IF(INDEX(食数記録!$C:$C,MATCH(4,内部計算!$Q:$Q,0))="","",INDEX(食数記録!$C:$C,MATCH(4,内部計算!$Q:$Q,0))&IF(IFERROR(VLOOKUP(INDEX(食数記録!$C:$C,MATCH(4,内部計算!$Q:$Q,0)),利用者名簿!$A:$I,9,0),"")<>"","("&VLOOKUP(INDEX(食数記録!$C:$C,MATCH(4,内部計算!$Q:$Q,0)),利用者名簿!$A:$I,9,0)&")","")),"") | F30: =IFERROR(IF(INDEX(食数記録!$C:$C,MATCH(4,内部計算!$S:$S,0))="","",INDEX(食数記録!$C:$C,MATCH(4,内部計算!$S:$S,0))&IF(IFERROR(VLOOKUP(INDEX(食数記録!$C:$C,MATCH(4,内部計算!$S:$S,0)),利用者名簿!$A:$I,9,0),"")<>"","("&VLOOKUP(INDEX(食数記録!$C:$C,MATCH(4,内部計算!$S:$S,0)),利用者名簿!$A:$I,9,0)&")","")),"")
B31: =IFERROR(IF(INDEX(食数記録!$C:$C,MATCH(5,内部計算!$O:$O,0))="","",INDEX(食数記録!$C:$C,MATCH(5,内部計算!$O:$O,0))&IF(IFERROR(VLOOKUP(INDEX(食数記録!$C:$C,MATCH(5,内部計算!$O:$O,0)),利用者名簿!$A:$I,9,0),"")<>"","("&VLOOKUP(INDEX(食数記録!$C:$C,MATCH(5,内部計算!$O:$O,0)),利用者名簿!$A:$I,9,0)&")","")),"") | D31: =IFERROR(IF(INDEX(食数記録!$C:$C,MATCH(5,内部計算!$Q:$Q,0))="","",INDEX(食数記録!$C:$C,MATCH(5,内部計算!$Q:$Q,0))&IF(IFERROR(VLOOKUP(INDEX(食数記録!$C:$C,MATCH(5,内部計算!$Q:$Q,0)),利用者名簿!$A:$I,9,0),"")<>"","("&VLOOKUP(INDEX(食数記録!$C:$C,MATCH(5,内部計算!$Q:$Q,0)),利用者名簿!$A:$I,9,0)&")","")),"") | F31: =IFERROR(IF(INDEX(食数記録!$C:$C,MATCH(5,内部計算!$S:$S,0))="","",INDEX(食数記録!$C:$C,MATCH(5,内部計算!$S:$S,0))&IF(IFERROR(VLOOKUP(INDEX(食数記録!$C:$C,MATCH(5,内部計算!$S:$S,0)),利用者名簿!$A:$I,9,0),"")<>"","("&VLOOKUP(INDEX(食数記録!$C:$C,MATCH(5,内部計算!$S:$S,0)),利用者名簿!$A:$I,9,0)&")","")),"")
B32: =IFERROR(IF(INDEX(食数記録!$C:$C,MATCH(6,内部計算!$O:$O,0))="","",INDEX(食数記録!$C:$C,MATCH(6,内部計算!$O:$O,0))&IF(IFERROR(VLOOKUP(INDEX(食数記録!$C:$C,MATCH(6,内部計算!$O:$O,0)),利用者名簿!$A:$I,9,0),"")<>"","("&VLOOKUP(INDEX(食数記録!$C:$C,MATCH(6,内部計算!$O:$O,0)),利用者名簿!$A:$I,9,0)&")","")),"") | D32: =IFERROR(IF(INDEX(食数記録!$C:$C,MATCH(6,内部計算!$Q:$Q,0))="","",INDEX(食数記録!$C:$C,MATCH(6,内部計算!$Q:$Q,0))&IF(IFERROR(VLOOKUP(INDEX(食数記録!$C:$C,MATCH(6,内部計算!$Q:$Q,0)),利用者名簿!$A:$I,9,0),"")<>"","("&VLOOKUP(INDEX(食数記録!$C:$C,MATCH(6,内部計算!$Q:$Q,0)),利用者名簿!$A:$I,9,0)&")","")),"") | F32: =IFERROR(IF(INDEX(食数記録!$C:$C,MATCH(6,内部計算!$S:$S,0))="","",INDEX(食数記録!$C:$C,MATCH(6,内部計算!$S:$S,0))&IF(IFERROR(VLOOKUP(INDEX(食数記録!$C:$C,MATCH(6,内部計算!$S:$S,0)),利用者名簿!$A:$I,9,0),"")<>"","("&VLOOKUP(INDEX(食数記録!$C:$C,MATCH(6,内部計算!$S:$S,0)),利用者名簿!$A:$I,9,0)&")","")),"")
B33: =IFERROR(IF(INDEX(食数記録!$C:$C,MATCH(7,内部計算!$O:$O,0))="","",INDEX(食数記録!$C:$C,MATCH(7,内部計算!$O:$O,0))&IF(IFERROR(VLOOKUP(INDEX(食数記録!$C:$C,MATCH(7,内部計算!$O:$O,0)),利用者名簿!$A:$I,9,0),"")<>"","("&VLOOKUP(INDEX(食数記録!$C:$C,MATCH(7,内部計算!$O:$O,0)),利用者名簿!$A:$I,9,0)&")","")),"") | D33: =IFERROR(IF(INDEX(食数記録!$C:$C,MATCH(7,内部計算!$Q:$Q,0))="","",INDEX(食数記録!$C:$C,MATCH(7,内部計算!$Q:$Q,0))&IF(IFERROR(VLOOKUP(INDEX(食数記録!$C:$C,MATCH(7,内部計算!$Q:$Q,0)),利用者名簿!$A:$I,9,0),"")<>"","("&VLOOKUP(INDEX(食数記録!$C:$C,MATCH(7,内部計算!$Q:$Q,0)),利用者名簿!$A:$I,9,0)&")","")),"") | F33: =IFERROR(IF(INDEX(食数記録!$C:$C,MATCH(7,内部計算!$S:$S,0))="","",INDEX(食数記録!$C:$C,MATCH(7,内部計算!$S:$S,0))&IF(IFERROR(VLOOKUP(INDEX(食数記録!$C:$C,MATCH(7,内部計算!$S:$S,0)),利用者名簿!$A:$I,9,0),"")<>"","("&VLOOKUP(INDEX(食数記録!$C:$C,MATCH(7,内部計算!$S:$S,0)),利用者名簿!$A:$I,9,0)&")","")),"")
B34: =IFERROR(IF(INDEX(食数記録!$C:$C,MATCH(8,内部計算!$O:$O,0))="","",INDEX(食数記録!$C:$C,MATCH(8,内部計算!$O:$O,0))&IF(IFERROR(VLOOKUP(INDEX(食数記録!$C:$C,MATCH(8,内部計算!$O:$O,0)),利用者名簿!$A:$I,9,0),"")<>"","("&VLOOKUP(INDEX(食数記録!$C:$C,MATCH(8,内部計算!$O:$O,0)),利用者名簿!$A:$I,9,0)&")","")),"") | D34: =IFERROR(IF(INDEX(食数記録!$C:$C,MATCH(8,内部計算!$Q:$Q,0))="","",INDEX(食数記録!$C:$C,MATCH(8,内部計算!$Q:$Q,0))&IF(IFERROR(VLOOKUP(INDEX(食数記録!$C:$C,MATCH(8,内部計算!$Q:$Q,0)),利用者名簿!$A:$I,9,0),"")<>"","("&VLOOKUP(INDEX(食数記録!$C:$C,MATCH(8,内部計算!$Q:$Q,0)),利用者名簿!$A:$I,9,0)&")","")),"") | F34: =IFERROR(IF(INDEX(食数記録!$C:$C,MATCH(8,内部計算!$S:$S,0))="","",INDEX(食数記録!$C:$C,MATCH(8,内部計算!$S:$S,0))&IF(IFERROR(VLOOKUP(INDEX(食数記録!$C:$C,MATCH(8,内部計算!$S:$S,0)),利用者名簿!$A:$I,9,0),"")<>"","("&VLOOKUP(INDEX(食数記録!$C:$C,MATCH(8,内部計算!$S:$S,0)),利用者名簿!$A:$I,9,0)&")","")),"")
A35: 女性GH | B35: =COUNTIFS(食数記録!$A:$A,$C$3,食数記録!$B:$B,"朝",食数記録!$F:$F,"女性GH",食数記録!$D:$D,"臨時喫食") -> 0 | D35: =COUNTIFS(食数記録!$A:$A,$C$3,食数記録!$B:$B,"昼",食数記録!$F:$F,"女性GH",食数記録!$D:$D,"臨時喫食") -> 0 | F35: =COUNTIFS(食数記録!$A:$A,$C$3,食数記録!$B:$B,"夕",食数記録!$F:$F,"女性GH",食数記録!$D:$D,"臨時喫食") -> 0
B36: =IFERROR(IF(INDEX(食数記録!$C:$C,MATCH(1,内部計算!$U:$U,0))="","",INDEX(食数記録!$C:$C,MATCH(1,内部計算!$U:$U,0))&IF(IFERROR(VLOOKUP(INDEX(食数記録!$C:$C,MATCH(1,内部計算!$U:$U,0)),利用者名簿!$A:$I,9,0),"")<>"","("&VLOOKUP(INDEX(食数記録!$C:$C,MATCH(1,内部計算!$U:$U,0)),利用者名簿!$A:$I,9,0)&")","")),"") | D36: =IFERROR(IF(INDEX(食数記録!$C:$C,MATCH(1,内部計算!$W:$W,0))="","",INDEX(食数記録!$C:$C,MATCH(1,内部計算!$W:$W,0))&IF(IFERROR(VLOOKUP(INDEX(食数記録!$C:$C,MATCH(1,内部計算!$W:$W,0)),利用者名簿!$A:$I,9,0),"")<>"","("&VLOOKUP(INDEX(食数記録!$C:$C,MATCH(1,内部計算!$W:$W,0)),利用者名簿!$A:$I,9,0)&")","")),"") | F36: =IFERROR(IF(INDEX(食数記録!$C:$C,MATCH(1,内部計算!$Y:$Y,0))="","",INDEX(食数記録!$C:$C,MATCH(1,内部計算!$Y:$Y,0))&IF(IFERROR(VLOOKUP(INDEX(食数記録!$C:$C,MATCH(1,内部計算!$Y:$Y,0)),利用者名簿!$A:$I,9,0),"")<>"","("&VLOOKUP(INDEX(食数記録!$C:$C,MATCH(1,内部計算!$Y:$Y,0)),利用者名簿!$A:$I,9,0)&")","")),"")
B37: =IFERROR(IF(INDEX(食数記録!$C:$C,MATCH(2,内部計算!$U:$U,0))="","",INDEX(食数記録!$C:$C,MATCH(2,内部計算!$U:$U,0))&IF(IFERROR(VLOOKUP(INDEX(食数記録!$C:$C,MATCH(2,内部計算!$U:$U,0)),利用者名簿!$A:$I,9,0),"")<>"","("&VLOOKUP(INDEX(食数記録!$C:$C,MATCH(2,内部計算!$U:$U,0)),利用者名簿!$A:$I,9,0)&")","")),"") | D37: =IFERROR(IF(INDEX(食数記録!$C:$C,MATCH(2,内部計算!$W:$W,0))="","",INDEX(食数記録!$C:$C,MATCH(2,内部計算!$W:$W,0))&IF(IFERROR(VLOOKUP(INDEX(食数記録!$C:$C,MATCH(2,内部計算!$W:$W,0)),利用者名簿!$A:$I,9,0),"")<>"","("&VLOOKUP(INDEX(食数記録!$C:$C,MATCH(2,内部計算!$W:$W,0)),利用者名簿!$A:$I,9,0)&")","")),"") | F37: =IFERROR(IF(INDEX(食数記録!$C:$C,MATCH(2,内部計算!$Y:$Y,0))="","",INDEX(食数記録!$C:$C,MATCH(2,内部計算!$Y:$Y,0))&IF(IFERROR(VLOOKUP(INDEX(食数記録!$C:$C,MATCH(2,内部計算!$Y:$Y,0)),利用者名簿!$A:$I,9,0),"")<>"","("&VLOOKUP(INDEX(食数記録!$C:$C,MATCH(2,内部計算!$Y:$Y,0)),利用者名簿!$A:$I,9,0)&")","")),"")
B38: =IFERROR(IF(INDEX(食数記録!$C:$C,MATCH(3,内部計算!$U:$U,0))="","",INDEX(食数記録!$C:$C,MATCH(3,内部計算!$U:$U,0))&IF(IFERROR(VLOOKUP(INDEX(食数記録!$C:$C,MATCH(3,内部計算!$U:$U,0)),利用者名簿!$A:$I,9,0),"")<>"","("&VLOOKUP(INDEX(食数記録!$C:$C,MATCH(3,内部計算!$U:$U,0)),利用者名簿!$A:$I,9,0)&")","")),"") | D38: =IFERROR(IF(INDEX(食数記録!$C:$C,MATCH(3,内部計算!$W:$W,0))="","",INDEX(食数記録!$C:$C,MATCH(3,内部計算!$W:$W,0))&IF(IFERROR(VLOOKUP(INDEX(食数記録!$C:$C,MATCH(3,内部計算!$W:$W,0)),利用者名簿!$A:$I,9,0),"")<>"","("&VLOOKUP(INDEX(食数記録!$C:$C,MATCH(3,内部計算!$W:$W,0)),利用者名簿!$A:$I,9,0)&")","")),"") | F38: =IFERROR(IF(INDEX(食数記録!$C:$C,MATCH(3,内部計算!$Y:$Y,0))="","",INDEX(食数記録!$C:$C,MATCH(3,内部計算!$Y:$Y,0))&IF(IFERROR(VLOOKUP(INDEX(食数記録!$C:$C,MATCH(3,内部計算!$Y:$Y,0)),利用者名簿!$A:$I,9,0),"")<>"","("&VLOOKUP(INDEX(食数記録!$C:$C,MATCH(3,内部計算!$Y:$Y,0)),利用者名簿!$A:$I,9,0)&")","")),"")
B39: =IFERROR(IF(INDEX(食数記録!$C:$C,MATCH(4,内部計算!$U:$U,0))="","",INDEX(食数記録!$C:$C,MATCH(4,内部計算!$U:$U,0))&IF(IFERROR(VLOOKUP(INDEX(食数記録!$C:$C,MATCH(4,内部計算!$U:$U,0)),利用者名簿!$A:$I,9,0),"")<>"","("&VLOOKUP(INDEX(食数記録!$C:$C,MATCH(4,内部計算!$U:$U,0)),利用者名簿!$A:$I,9,0)&")","")),"") | D39: =IFERROR(IF(INDEX(食数記録!$C:$C,MATCH(4,内部計算!$W:$W,0))="","",INDEX(食数記録!$C:$C,MATCH(4,内部計算!$W:$W,0))&IF(IFERROR(VLOOKUP(INDEX(食数記録!$C:$C,MATCH(4,内部計算!$W:$W,0)),利用者名簿!$A:$I,9,0),"")<>"","("&VLOOKUP(INDEX(食数記録!$C:$C,MATCH(4,内部計算!$W:$W,0)),利用者名簿!$A:$I,9,0)&")","")),"") | F39: =IFERROR(IF(INDEX(食数記録!$C:$C,MATCH(4,内部計算!$Y:$Y,0))="","",INDEX(食数記録!$C:$C,MATCH(4,内部計算!$Y:$Y,0))&IF(IFERROR(VLOOKUP(INDEX(食数記録!$C:$C,MATCH(4,内部計算!$Y:$Y,0)),利用者名簿!$A:$I,9,0),"")<>"","("&VLOOKUP(INDEX(食数記録!$C:$C,MATCH(4,内部計算!$Y:$Y,0)),利用者名簿!$A:$I,9,0)&")","")),"")
B40: =IFERROR(IF(INDEX(食数記録!$C:$C,MATCH(5,内部計算!$U:$U,0))="","",INDEX(食数記録!$C:$C,MATCH(5,内部計算!$U:$U,0))&IF(IFERROR(VLOOKUP(INDEX(食数記録!$C:$C,MATCH(5,内部計算!$U:$U,0)),利用者名簿!$A:$I,9,0),"")<>"","("&VLOOKUP(INDEX(食数記録!$C:$C,MATCH(5,内部計算!$U:$U,0)),利用者名簿!$A:$I,9,0)&")","")),"") | D40: =IFERROR(IF(INDEX(食数記録!$C:$C,MATCH(5,内部計算!$W:$W,0))="","",INDEX(食数記録!$C:$C,MATCH(5,内部計算!$W:$W,0))&IF(IFERROR(VLOOKUP(INDEX(食数記録!$C:$C,MATCH(5,内部計算!$W:$W,0)),利用者名簿!$A:$I,9,0),"")<>"","("&VLOOKUP(INDEX(食数記録!$C:$C,MATCH(5,内部計算!$W:$W,0)),利用者名簿!$A:$I,9,0)&")","")),"") | F40: =IFERROR(IF(INDEX(食数記録!$C:$C,MATCH(5,内部計算!$Y:$Y,0))="","",INDEX(食数記録!$C:$C,MATCH(5,内部計算!$Y:$Y,0))&IF(IFERROR(VLOOKUP(INDEX(食数記録!$C:$C,MATCH(5,内部計算!$Y:$Y,0)),利用者名簿!$A:$I,9,0),"")<>"","("&VLOOKUP(INDEX(食数記録!$C:$C,MATCH(5,内部計算!$Y:$Y,0)),利用者名簿!$A:$I,9,0)&")","")),"")
B41: =IFERROR(IF(INDEX(食数記録!$C:$C,MATCH(6,内部計算!$U:$U,0))="","",INDEX(食数記録!$C:$C,MATCH(6,内部計算!$U:$U,0))&IF(IFERROR(VLOOKUP(INDEX(食数記録!$C:$C,MATCH(6,内部計算!$U:$U,0)),利用者名簿!$A:$I,9,0),"")<>"","("&VLOOKUP(INDEX(食数記録!$C:$C,MATCH(6,内部計算!$U:$U,0)),利用者名簿!$A:$I,9,0)&")","")),"") | D41: =IFERROR(IF(INDEX(食数記録!$C:$C,MATCH(6,内部計算!$W:$W,0))="","",INDEX(食数記録!$C:$C,MATCH(6,内部計算!$W:$W,0))&IF(IFERROR(VLOOKUP(INDEX(食数記録!$C:$C,MATCH(6,内部計算!$W:$W,0)),利用者名簿!$A:$I,9,0),"")<>"","("&VLOOKUP(INDEX(食数記録!$C:$C,MATCH(6,内部計算!$W:$W,0)),利用者名簿!$A:$I,9,0)&")","")),"") | F41: =IFERROR(IF(INDEX(食数記録!$C:$C,MATCH(6,内部計算!$Y:$Y,0))="","",INDEX(食数記録!$C:$C,MATCH(6,内部計算!$Y:$Y,0))&IF(IFERROR(VLOOKUP(INDEX(食数記録!$C:$C,MATCH(6,内部計算!$Y:$Y,0)),利用者名簿!$A:$I,9,0),"")<>"","("&VLOOKUP(INDEX(食数記録!$C:$C,MATCH(6,内部計算!$Y:$Y,0)),利用者名簿!$A:$I,9,0)&")","")),"")
B42: =IFERROR(IF(INDEX(食数記録!$C:$C,MATCH(7,内部計算!$U:$U,0))="","",INDEX(食数記録!$C:$C,MATCH(7,内部計算!$U:$U,0))&IF(IFERROR(VLOOKUP(INDEX(食数記録!$C:$C,MATCH(7,内部計算!$U:$U,0)),利用者名簿!$A:$I,9,0),"")<>"","("&VLOOKUP(INDEX(食数記録!$C:$C,MATCH(7,内部計算!$U:$U,0)),利用者名簿!$A:$I,9,0)&")","")),"") | D42: =IFERROR(IF(INDEX(食数記録!$C:$C,MATCH(7,内部計算!$W:$W,0))="","",INDEX(食数記録!$C:$C,MATCH(7,内部計算!$W:$W,0))&IF(IFERROR(VLOOKUP(INDEX(食数記録!$C:$C,MATCH(7,内部計算!$W:$W,0)),利用者名簿!$A:$I,9,0),"")<>"","("&VLOOKUP(INDEX(食数記録!$C:$C,MATCH(7,内部計算!$W:$W,0)),利用者名簿!$A:$I,9,0)&")","")),"") | F42: =IFERROR(IF(INDEX(食数記録!$C:$C,MATCH(7,内部計算!$Y:$Y,0))="","",INDEX(食数記録!$C:$C,MATCH(7,内部計算!$Y:$Y,0))&IF(IFERROR(VLOOKUP(INDEX(食数記録!$C:$C,MATCH(7,内部計算!$Y:$Y,0)),利用者名簿!$A:$I,9,0),"")<>"","("&VLOOKUP(INDEX(食数記録!$C:$C,MATCH(7,内部計算!$Y:$Y,0)),利用者名簿!$A:$I,9,0)&")","")),"")
...

Sheet 月次集計
A1: 月次集計（食単価清算用）
A3: 対象年月（1日を入力） | C3: 46235
A4: ※GH利用者は「平日昼は基本的に喫食」という標準ルールをこの集計のみ自動適用します（清算金額に直結するため、名簿の在籍者数から平日昼の標準喫食人数を計算し、欠食登録があれば差し引きます）。
A5: ※日付が対象月の日数を超える行（29〜31日目で該当月に存在しない日）は空欄になります。
A7: 月間合計食数
B8: 朝食 | D8: 昼食 | F8: 夕食
B9: =SUM(C13:C43) -> 61 | D9: =SUM(D13:D43) -> 84 | F9: =SUM(E13:E43) -> 62
A12: 日付 | B12: 曜日 | C12: 朝食計 | D12: 昼食計 | E12: 夕食計
A13: =IF(MONTH($C$3+0)=MONTH($C$3),$C$3+0,"") -> 46235 | B13: =IF(A13="","",TEXT(A13,"aaa")) -> Sat | C13: =IF($A13="","",(COUNTIFS(利用者名簿!$B:$B,"男性入所",利用者名簿!$G:$G,"在籍")-COUNTIFS(食数記録!$A:$A,$A13,食数記録!$B:$B,"朝",食数記録!$F:$F,"男性入所",食数記録!$D:$D,"欠食"))+(COUNTIFS(利用者名簿!$B:$B,"女性入所",利用者名簿!$G:$G,"在籍")-COUNTIFS(食数記録!$A:$A,$A13,食数記録!$B:$B,"朝",食数記録!$F:$F,"女性入所",食数記録!$D:$D,"欠食"))+COUNTIFS(食数記録!$A:$A,$A13,食数記録!$B:$B,"朝",食数記録!$F:$F,"男性GH",食数記録!$D:$D,"臨時喫食")+COUNTIFS(食数記録!$A:$A,$A13,食数記録!$B:$B,"朝",食数記録!$F:$F,"女性GH",食数記録!$D:$D,"臨時喫食")+SUMIFS(職員食来客記録!$C:$C,職員食来客記録!$A:$A,$A13,職員食来客記録!$B:$B,"朝")+SUMIFS(職員食来客記録!$D:$D,職員食来客記録!$A:$A,$A13,職員食来客記録!$B:$B,"朝")) -> 2 | D13: =IF($A13="","",(COUNTIFS(利用者名簿!$B:$B,"男性入所",利用者名簿!$G:$G,"在籍")-COUNTIFS(食数記録!$A:$A,$A13,食数記録!$B:$B,"昼",食数記録!$F:$F,"男性入所",食数記録!$D:$D,"欠食"))+(COUNTIFS(利用者名簿!$B:$B,"女性入所",利用者名簿!$G:$G,"在籍")-COUNTIFS(食数記録!$A:$A,$A13,食数記録!$B:$B,"昼",食数記録!$F:$F,"女性入所",食数記録!$D:$D,"欠食"))+(IF(WEEKDAY($A13,2)<=5,COUNTIFS(利用者名簿!$B:$B,"男性GH",利用者名簿!$G:$G,"在籍")-COUNTIFS(食数記録!$A:$A,$A13,食数記録!$B:$B,"昼",食数記録!$F:$F,"男性GH",食数記録!$D:$D,"欠食"),COUNTIFS(食数記録!$A:$A,$A13,食数記録!$B:$B,"昼",食数記録!$F:$F,"男性GH",食数記録!$D:$D,"臨時喫食")))+(IF(WEEKDAY($A13,2)<=5,COUNTIFS(利用者名簿!$B:$B,"女性GH",利用者名簿!$G:$G,"在籍")-COUNTIFS(食数記録!$A:$A,$A13,食数記録!$B:$B,"昼",食数記録!$F:$F,"女性GH",食数記録!$D:$D,"欠食"),COUNTIFS(食数記録!$A:$A,$A13,食数記録!$B:$B,"昼",食数記録!$F:$F,"女性GH",食数記録!$D:$D,"臨時喫食")))+SUMIFS(職員食来客記録!$C:$C,職員食来客記録!$A:$A,$A13,職員食来客記録!$B:$B,"昼")+SUMIFS(職員食来客記録!$D:$D,職員食来客記録!$A:$A,$A13,職員食来客記録!$B:$B,"昼")) -> 2 | E13: =IF($A13="","",(COUNTIFS(利用者名簿!$B:$B,"男性入所",利用者名簿!$G:$G,"在籍")-COUNTIFS(食数記録!$A:$A,$A13,食数記録!$B:$B,"夕",食数記録!$F:$F,"男性入所",食数記録!$D:$D,"欠食"))+(COUNTIFS(利用者名簿!$B:$B,"女性入所",利用者名簿!$G:$G,"在籍")-COUNTIFS(食数記録!$A:$A,$A13,食数記録!$B:$B,"夕",食数記録!$F:$F,"女性入所",食数記録!$D:$D,"欠食"))+COUNTIFS(食数記録!$A:$A,$A13,食数記録!$B:$B,"夕",食数記録!$F:$F,"男性GH",食数記録!$D:$D,"臨時喫食")+COUNTIFS(食数記録!$A:$A,$A13,食数記録!$B:$B,"夕",食数記録!$F:$F,"女性GH",食数記録!$D:$D,"臨時喫食")+SUMIFS(職員食来客記録!$C:$C,職員食来客記録!$A:$A,$A13,職員食来客記録!$B:$B,"夕")+SUMIFS(職員食来客記録!$D:$D,職員食来客記録!$A:$A,$A13,職員食来客記録!$B:$B,"夕")) -> 2
A14: =IF(MONTH($C$3+1)=MONTH($C$3),$C$3+1,"") -> 46236 | B14: =IF(A14="","",TEXT(A14,"aaa")) -> Sun | C14: =IF($A14="","",(COUNTIFS(利用者名簿!$B:$B,"男性入所",利用者名簿!$G:$G,"在籍")-COUNTIFS(食数記録!$A:$A,$A14,食数記録!$B:$B,"朝",食数記録!$F:$F,"男性入所",食数記録!$D:$D,"欠食"))+(COUNTIFS(利用者名簿!$B:$B,"女性入所",利用者名簿!$G:$G,"在籍")-COUNTIFS(食数記録!$A:$A,$A14,食数記録!$B:$B,"朝",食数記録!$F:$F,"女性入所",食数記録!$D:$D,"欠食"))+COUNTIFS(食数記録!$A:$A,$A14,食数記録!$B:$B,"朝",食数記録!$F:$F,"男性GH",食数記録!$D:$D,"臨時喫食")+COUNTIFS(食数記録!$A:$A,$A14,食数記録!$B:$B,"朝",食数記録!$F:$F,"女性GH",食数記録!$D:$D,"臨時喫食")+SUMIFS(職員食来客記録!$C:$C,職員食来客記録!$A:$A,$A14,職員食来客記録!$B:$B,"朝")+SUMIFS(職員食来客記録!$D:$D,職員食来客記録!$A:$A,$A14,職員食来客記録!$B:$B,"朝")) -> 2 | D14: =IF($A14="","",(COUNTIFS(利用者名簿!$B:$B,"男性入所",利用者名簿!$G:$G,"在籍")-COUNTIFS(食数記録!$A:$A,$A14,食数記録!$B:$B,"昼",食数記録!$F:$F,"男性入所",食数記録!$D:$D,"欠食"))+(COUNTIFS(利用者名簿!$B:$B,"女性入所",利用者名簿!$G:$G,"在籍")-COUNTIFS(食数記録!$A:$A,$A14,食数記録!$B:$B,"昼",食数記録!$F:$F,"女性入所",食数記録!$D:$D,"欠食"))+(IF(WEEKDAY($A14,2)<=5,COUNTIFS(利用者名簿!$B:$B,"男性GH",利用者名簿!$G:$G,"在籍")-COUNTIFS(食数記録!$A:$A,$A14,食数記録!$B:$B,"昼",食数記録!$F:$F,"男性GH",食数記録!$D:$D,"欠食"),COUNTIFS(食数記録!$A:$A,$A14,食数記録!$B:$B,"昼",食数記録!$F:$F,"男性GH",食数記録!$D:$D,"臨時喫食")))+(IF(WEEKDAY($A14,2)<=5,COUNTIFS(利用者名簿!$B:$B,"女性GH",利用者名簿!$G:$G,"在籍")-COUNTIFS(食数記録!$A:$A,$A14,食数記録!$B:$B,"昼",食数記録!$F:$F,"女性GH",食数記録!$D:$D,"欠食"),COUNTIFS(食数記録!$A:$A,$A14,食数記録!$B:$B,"昼",食数記録!$F:$F,"女性GH",食数記録!$D:$D,"臨時喫食")))+SUMIFS(職員食来客記録!$C:$C,職員食来客記録!$A:$A,$A14,職員食来客記録!$B:$B,"昼")+SUMIFS(職員食来客記録!$D:$D,職員食来客記録!$A:$A,$A14,職員食来客記録!$B:$B,"昼")) -> 2 | E14: =IF($A14="","",(COUNTIFS(利用者名簿!$B:$B,"男性入所",利用者名簿!$G:$G,"在籍")-COUNTIFS(食数記録!$A:$A,$A14,食数記録!$B:$B,"夕",食数記録!$F:$F,"男性入所",食数記録!$D:$D,"欠食"))+(COUNTIFS(利用者名簿!$B:$B,"女性入所",利用者名簿!$G:$G,"在籍")-COUNTIFS(食数記録!$A:$A,$A14,食数記録!$B:$B,"夕",食数記録!$F:$F,"女性入所",食数記録!$D:$D,"欠食"))+COUNTIFS(食数記録!$A:$A,$A14,食数記録!$B:$B,"夕",食数記録!$F:$F,"男性GH",食数記録!$D:$D,"臨時喫食")+COUNTIFS(食数記録!$A:$A,$A14,食数記録!$B:$B,"夕",食数記録!$F:$F,"女性GH",食数記録!$D:$D,"臨時喫食")+SUMIFS(職員食来客記録!$C:$C,職員食来客記録!$A:$A,$A14,職員食来客記録!$B:$B,"夕")+SUMIFS(職員食来客記録!$D:$D,職員食来客記録!$A:$A,$A14,職員食来客記録!$B:$B,"夕")) -> 2
A15: =IF(MONTH($C$3+2)=MONTH($C$3),$C$3+2,"") -> 46237 | B15: =IF(A15="","",TEXT(A15,"aaa")) -> Mon | C15: =IF($A15="","",(COUNTIFS(利用者名簿!$B:$B,"男性入所",利用者名簿!$G:$G,"在籍")-COUNTIFS(食数記録!$A:$A,$A15,食数記録!$B:$B,"朝",食数記録!$F:$F,"男性入所",食数記録!$D:$D,"欠食"))+(COUNTIFS(利用者名簿!$B:$B,"女性入所",利用者名簿!$G:$G,"在籍")-COUNTIFS(食数記録!$A:$A,$A15,食数記録!$B:$B,"朝",食数記録!$F:$F,"女性入所",食数記録!$D:$D,"欠食"))+COUNTIFS(食数記録!$A:$A,$A15,食数記録!$B:$B,"朝",食数記録!$F:$F,"男性GH",食数記録!$D:$D,"臨時喫食")+COUNTIFS(食数記録!$A:$A,$A15,食数記録!$B:$B,"朝",食数記録!$F:$F,"女性GH",食数記録!$D:$D,"臨時喫食")+SUMIFS(職員食来客記録!$C:$C,職員食来客記録!$A:$A,$A15,職員食来客記録!$B:$B,"朝")+SUMIFS(職員食来客記録!$D:$D,職員食来客記録!$A:$A,$A15,職員食来客記録!$B:$B,"朝")) -> 2 | D15: =IF($A15="","",(COUNTIFS(利用者名簿!$B:$B,"男性入所",利用者名簿!$G:$G,"在籍")-COUNTIFS(食数記録!$A:$A,$A15,食数記録!$B:$B,"昼",食数記録!$F:$F,"男性入所",食数記録!$D:$D,"欠食"))+(COUNTIFS(利用者名簿!$B:$B,"女性入所",利用者名簿!$G:$G,"在籍")-COUNTIFS(食数記録!$A:$A,$A15,食数記録!$B:$B,"昼",食数記録!$F:$F,"女性入所",食数記録!$D:$D,"欠食"))+(IF(WEEKDAY($A15,2)<=5,COUNTIFS(利用者名簿!$B:$B,"男性GH",利用者名簿!$G:$G,"在籍")-COUNTIFS(食数記録!$A:$A,$A15,食数記録!$B:$B,"昼",食数記録!$F:$F,"男性GH",食数記録!$D:$D,"欠食"),COUNTIFS(食数記録!$A:$A,$A15,食数記録!$B:$B,"昼",食数記録!$F:$F,"男性GH",食数記録!$D:$D,"臨時喫食")))+(IF(WEEKDAY($A15,2)<=5,COUNTIFS(利用者名簿!$B:$B,"女性GH",利用者名簿!$G:$G,"在籍")-COUNTIFS(食数記録!$A:$A,$A15,食数記録!$B:$B,"昼",食数記録!$F:$F,"女性GH",食数記録!$D:$D,"欠食"),COUNTIFS(食数記録!$A:$A,$A15,食数記録!$B:$B,"昼",食数記録!$F:$F,"女性GH",食数記録!$D:$D,"臨時喫食")))+SUMIFS(職員食来客記録!$C:$C,職員食来客記録!$A:$A,$A15,職員食来客記録!$B:$B,"昼")+SUMIFS(職員食来客記録!$D:$D,職員食来客記録!$A:$A,$A15,職員食来客記録!$B:$B,"昼")) -> 3 | E15: =IF($A15="","",(COUNTIFS(利用者名簿!$B:$B,"男性入所",利用者名簿!$G:$G,"在籍")-COUNTIFS(食数記録!$A:$A,$A15,食数記録!$B:$B,"夕",食数記録!$F:$F,"男性入所",食数記録!$D:$D,"欠食"))+(COUNTIFS(利用者名簿!$B:$B,"女性入所",利用者名簿!$G:$G,"在籍")-COUNTIFS(食数記録!$A:$A,$A15,食数記録!$B:$B,"夕",食数記録!$F:$F,"女性入所",食数記録!$D:$D,"欠食"))+COUNTIFS(食数記録!$A:$A,$A15,食数記録!$B:$B,"夕",食数記録!$F:$F,"男性GH",食数記録!$D:$D,"臨時喫食")+COUNTIFS(食数記録!$A:$A,$A15,食数記録!$B:$B,"夕",食数記録!$F:$F,"女性GH",食数記録!$D:$D,"臨時喫食")+SUMIFS(職員食来客記録!$C:$C,職員食来客記録!$A:$A,$A15,職員食来客記録!$B:$B,"夕")+SUMIFS(職員食来客記録!$D:$D,職員食来客記録!$A:$A,$A15,職員食来客記録!$B:$B,"夕")) -> 2
A16: =IF(MONTH($C$3+3)=MONTH($C$3),$C$3+3,"") -> 46238 | B16: =IF(A16="","",TEXT(A16,"aaa")) -> Tue | C16: =IF($A16="","",(COUNTIFS(利用者名簿!$B:$B,"男性入所",利用者名簿!$G:$G,"在籍")-COUNTIFS(食数記録!$A:$A,$A16,食数記録!$B:$B,"朝",食数記録!$F:$F,"男性入所",食数記録!$D:$D,"欠食"))+(COUNTIFS(利用者名簿!$B:$B,"女性入所",利用者名簿!$G:$G,"在籍")-COUNTIFS(食数記録!$A:$A,$A16,食数記録!$B:$B,"朝",食数記録!$F:$F,"女性入所",食数記録!$D:$D,"欠食"))+COUNTIFS(食数記録!$A:$A,$A16,食数記録!$B:$B,"朝",食数記録!$F:$F,"男性GH",食数記録!$D:$D,"臨時喫食")+COUNTIFS(食数記録!$A:$A,$A16,食数記録!$B:$B,"朝",食数記録!$F:$F,"女性GH",食数記録!$D:$D,"臨時喫食")+SUMIFS(職員食来客記録!$C:$C,職員食来客記録!$A:$A,$A16,職員食来客記録!$B:$B,"朝")+SUMIFS(職員食来客記録!$D:$D,職員食来客記録!$A:$A,$A16,職員食来客記録!$B:$B,"朝")) -> 2 | D16: =IF($A16="","",(COUNTIFS(利用者名簿!$B:$B,"男性入所",利用者名簿!$G:$G,"在籍")-COUNTIFS(食数記録!$A:$A,$A16,食数記録!$B:$B,"昼",食数記録!$F:$F,"男性入所",食数記録!$D:$D,"欠食"))+(COUNTIFS(利用者名簿!$B:$B,"女性入所",利用者名簿!$G:$G,"在籍")-COUNTIFS(食数記録!$A:$A,$A16,食数記録!$B:$B,"昼",食数記録!$F:$F,"女性入所",食数記録!$D:$D,"欠食"))+(IF(WEEKDAY($A16,2)<=5,COUNTIFS(利用者名簿!$B:$B,"男性GH",利用者名簿!$G:$G,"在籍")-COUNTIFS(食数記録!$A:$A,$A16,食数記録!$B:$B,"昼",食数記録!$F:$F,"男性GH",食数記録!$D:$D,"欠食"),COUNTIFS(食数記録!$A:$A,$A16,食数記録!$B:$B,"昼",食数記録!$F:$F,"男性GH",食数記録!$D:$D,"臨時喫食")))+(IF(WEEKDAY($A16,2)<=5,COUNTIFS(利用者名簿!$B:$B,"女性GH",利用者名簿!$G:$G,"在籍")-COUNTIFS(食数記録!$A:$A,$A16,食数記録!$B:$B,"昼",食数記録!$F:$F,"女性GH",食数記録!$D:$D,"欠食"),COUNTIFS(食数記録!$A:$A,$A16,食数記録!$B:$B,"昼",食数記録!$F:$F,"女性GH",食数記録!$D:$D,"臨時喫食")))+SUMIFS(職員食来客記録!$C:$C,職員食来客記録!$A:$A,$A16,職員食来客記録!$B:$B,"昼")+SUMIFS(職員食来客記録!$D:$D,職員食来客記録!$A:$A,$A16,職員食来客記録!$B:$B,"昼")) -> 3 | E16: =IF($A16="","",(COUNTIFS(利用者名簿!$B:$B,"男性入所",利用者名簿!$G:$G,"在籍")-COUNTIFS(食数記録!$A:$A,$A16,食数記録!$B:$B,"夕",食数記録!$F:$F,"男性入所",食数記録!$D:$D,"欠食"))+(COUNTIFS(利用者名簿!$B:$B,"女性入所",利用者名簿!$G:$G,"在籍")-COUNTIFS(食数記録!$A:$A,$A16,食数記録!$B:$B,"夕",食数記録!$F:$F,"女性入所",食数記録!$D:$D,"欠食"))+COUNTIFS(食数記録!$A:$A,$A16,食数記録!$B:$B,"夕",食数記録!$F:$F,"男性GH",食数記録!$D:$D,"臨時喫食")+COUNTIFS(食数記録!$A:$A,$A16,食数記録!$B:$B,"夕",食数記録!$F:$F,"女性GH",食数記録!$D:$D,"臨時喫食")+SUMIFS(職員食来客記録!$C:$C,職員食来客記録!$A:$A,$A16,職員食来客記録!$B:$B,"夕")+SUMIFS(職員食来客記録!$D:$D,職員食来客記録!$A:$A,$A16,職員食来客記録!$B:$B,"夕")) -> 2
A17: =IF(MONTH($C$3+4)=MONTH($C$3),$C$3+4,"") -> 46239 | B17: =IF(A17="","",TEXT(A17,"aaa")) -> Wed | C17: =IF($A17="","",(COUNTIFS(利用者名簿!$B:$B,"男性入所",利用者名簿!$G:$G,"在籍")-COUNTIFS(食数記録!$A:$A,$A17,食数記録!$B:$B,"朝",食数記録!$F:$F,"男性入所",食数記録!$D:$D,"欠食"))+(COUNTIFS(利用者名簿!$B:$B,"女性入所",利用者名簿!$G:$G,"在籍")-COUNTIFS(食数記録!$A:$A,$A17,食数記録!$B:$B,"朝",食数記録!$F:$F,"女性入所",食数記録!$D:$D,"欠食"))+COUNTIFS(食数記録!$A:$A,$A17,食数記録!$B:$B,"朝",食数記録!$F:$F,"男性GH",食数記録!$D:$D,"臨時喫食")+COUNTIFS(食数記録!$A:$A,$A17,食数記録!$B:$B,"朝",食数記録!$F:$F,"女性GH",食数記録!$D:$D,"臨時喫食")+SUMIFS(職員食来客記録!$C:$C,職員食来客記録!$A:$A,$A17,職員食来客記録!$B:$B,"朝")+SUMIFS(職員食来客記録!$D:$D,職員食来客記録!$A:$A,$A17,職員食来客記録!$B:$B,"朝")) -> 2 | D17: =IF($A17="","",(COUNTIFS(利用者名簿!$B:$B,"男性入所",利用者名簿!$G:$G,"在籍")-COUNTIFS(食数記録!$A:$A,$A17,食数記録!$B:$B,"昼",食数記録!$F:$F,"男性入所",食数記録!$D:$D,"欠食"))+(COUNTIFS(利用者名簿!$B:$B,"女性入所",利用者名簿!$G:$G,"在籍")-COUNTIFS(食数記録!$A:$A,$A17,食数記録!$B:$B,"昼",食数記録!$F:$F,"女性入所",食数記録!$D:$D,"欠食"))+(IF(WEEKDAY($A17,2)<=5,COUNTIFS(利用者名簿!$B:$B,"男性GH",利用者名簿!$G:$G,"在籍")-COUNTIFS(食数記録!$A:$A,$A17,食数記録!$B:$B,"昼",食数記録!$F:$F,"男性GH",食数記録!$D:$D,"欠食"),COUNTIFS(食数記録!$A:$A,$A17,食数記録!$B:$B,"昼",食数記録!$F:$F,"男性GH",食数記録!$D:$D,"臨時喫食")))+(IF(WEEKDAY($A17,2)<=5,COUNTIFS(利用者名簿!$B:$B,"女性GH",利用者名簿!$G:$G,"在籍")-COUNTIFS(食数記録!$A:$A,$A17,食数記録!$B:$B,"昼",食数記録!$F:$F,"女性GH",食数記録!$D:$D,"欠食"),COUNTIFS(食数記録!$A:$A,$A17,食数記録!$B:$B,"昼",食数記録!$F:$F,"女性GH",食数記録!$D:$D,"臨時喫食")))+SUMIFS(職員食来客記録!$C:$C,職員食来客記録!$A:$A,$A17,職員食来客記録!$B:$B,"昼")+SUMIFS(職員食来客記録!$D:$D,職員食来客記録!$A:$A,$A17,職員食来客記録!$B:$B,"昼")) -> 3 | E17: =IF($A17="","",(COUNTIFS(利用者名簿!$B:$B,"男性入所",利用者名簿!$G:$G,"在籍")-COUNTIFS(食数記録!$A:$A,$A17,食数記録!$B:$B,"夕",食数記録!$F:$F,"男性入所",食数記録!$D:$D,"欠食"))+(COUNTIFS(利用者名簿!$B:$B,"女性入所",利用者名簿!$G:$G,"在籍")-COUNTIFS(食数記録!$A:$A,$A17,食数記録!$B:$B,"夕",食数記録!$F:$F,"女性入所",食数記録!$D:$D,"欠食"))+COUNTIFS(食数記録!$A:$A,$A17,食数記録!$B:$B,"夕",食数記録!$F:$F,"男性GH",食数記録!$D:$D,"臨時喫食")+COUNTIFS(食数記録!$A:$A,$A17,食数記録!$B:$B,"夕",食数記録!$F:$F,"女性GH",食数記録!$D:$D,"臨時喫食")+SUMIFS(職員食来客記録!$C:$C,職員食来客記録!$A:$A,$A17,職員食来客記録!$B:$B,"夕")+SUMIFS(職員食来客記録!$D:$D,職員食来客記録!$A:$A,$A17,職員食来客記録!$B:$B,"夕")) -> 2
A18: =IF(MONTH($C$3+5)=MONTH($C$3),$C$3+5,"") -> 46240 | B18: =IF(A18="","",TEXT(A18,"aaa")) -> Thu | C18: =IF($A18="","",(COUNTIFS(利用者名簿!$B:$B,"男性入所",利用者名簿!$G:$G,"在籍")-COUNTIFS(食数記録!$A:$A,$A18,食数記録!$B:$B,"朝",食数記録!$F:$F,"男性入所",食数記録!$D:$D,"欠食"))+(COUNTIFS(利用者名簿!$B:$B,"女性入所",利用者名簿!$G:$G,"在籍")-COUNTIFS(食数記録!$A:$A,$A18,食数記録!$B:$B,"朝",食数記録!$F:$F,"女性入所",食数記録!$D:$D,"欠食"))+COUNTIFS(食数記録!$A:$A,$A18,食数記録!$B:$B,"朝",食数記録!$F:$F,"男性GH",食数記録!$D:$D,"臨時喫食")+COUNTIFS(食数記録!$A:$A,$A18,食数記録!$B:$B,"朝",食数記録!$F:$F,"女性GH",食数記録!$D:$D,"臨時喫食")+SUMIFS(職員食来客記録!$C:$C,職員食来客記録!$A:$A,$A18,職員食来客記録!$B:$B,"朝")+SUMIFS(職員食来客記録!$D:$D,職員食来客記録!$A:$A,$A18,職員食来客記録!$B:$B,"朝")) -> 2 | D18: =IF($A18="","",(COUNTIFS(利用者名簿!$B:$B,"男性入所",利用者名簿!$G:$G,"在籍")-COUNTIFS(食数記録!$A:$A,$A18,食数記録!$B:$B,"昼",食数記録!$F:$F,"男性入所",食数記録!$D:$D,"欠食"))+(COUNTIFS(利用者名簿!$B:$B,"女性入所",利用者名簿!$G:$G,"在籍")-COUNTIFS(食数記録!$A:$A,$A18,食数記録!$B:$B,"昼",食数記録!$F:$F,"女性入所",食数記録!$D:$D,"欠食"))+(IF(WEEKDAY($A18,2)<=5,COUNTIFS(利用者名簿!$B:$B,"男性GH",利用者名簿!$G:$G,"在籍")-COUNTIFS(食数記録!$A:$A,$A18,食数記録!$B:$B,"昼",食数記録!$F:$F,"男性GH",食数記録!$D:$D,"欠食"),COUNTIFS(食数記録!$A:$A,$A18,食数記録!$B:$B,"昼",食数記録!$F:$F,"男性GH",食数記録!$D:$D,"臨時喫食")))+(IF(WEEKDAY($A18,2)<=5,COUNTIFS(利用者名簿!$B:$B,"女性GH",利用者名簿!$G:$G,"在籍")-COUNTIFS(食数記録!$A:$A,$A18,食数記録!$B:$B,"昼",食数記録!$F:$F,"女性GH",食数記録!$D:$D,"欠食"),COUNTIFS(食数記録!$A:$A,$A18,食数記録!$B:$B,"昼",食数記録!$F:$F,"女性GH",食数記録!$D:$D,"臨時喫食")))+SUMIFS(職員食来客記録!$C:$C,職員食来客記録!$A:$A,$A18,職員食来客記録!$B:$B,"昼")+SUMIFS(職員食来客記録!$D:$D,職員食来客記録!$A:$A,$A18,職員食来客記録!$B:$B,"昼")) -> 3 | E18: =IF($A18="","",(COUNTIFS(利用者名簿!$B:$B,"男性入所",利用者名簿!$G:$G,"在籍")-COUNTIFS(食数記録!$A:$A,$A18,食数記録!$B:$B,"夕",食数記録!$F:$F,"男性入所",食数記録!$D:$D,"欠食"))+(COUNTIFS(利用者名簿!$B:$B,"女性入所",利用者名簿!$G:$G,"在籍")-COUNTIFS(食数記録!$A:$A,$A18,食数記録!$B:$B,"夕",食数記録!$F:$F,"女性入所",食数記録!$D:$D,"欠食"))+COUNTIFS(食数記録!$A:$A,$A18,食数記録!$B:$B,"夕",食数記録!$F:$F,"男性GH",食数記録!$D:$D,"臨時喫食")+COUNTIFS(食数記録!$A:$A,$A18,食数記録!$B:$B,"夕",食数記録!$F:$F,"女性GH",食数記録!$D:$D,"臨時喫食")+SUMIFS(職員食来客記録!$C:$C,職員食来客記録!$A:$A,$A18,職員食来客記録!$B:$B,"夕")+SUMIFS(職員食来客記録!$D:$D,職員食来客記録!$A:$A,$A18,職員食来客記録!$B:$B,"夕")) -> 2
A19: =IF(MONTH($C$3+6)=MONTH($C$3),$C$3+6,"") -> 46241 | B19: =IF(A19="","",TEXT(A19,"aaa")) -> Fri | C19: =IF($A19="","",(COUNTIFS(利用者名簿!$B:$B,"男性入所",利用者名簿!$G:$G,"在籍")-COUNTIFS(食数記録!$A:$A,$A19,食数記録!$B:$B,"朝",食数記録!$F:$F,"男性入所",食数記録!$D:$D,"欠食"))+(COUNTIFS(利用者名簿!$B:$B,"女性入所",利用者名簿!$G:$G,"在籍")-COUNTIFS(食数記録!$A:$A,$A19,食数記録!$B:$B,"朝",食数記録!$F:$F,"女性入所",食数記録!$D:$D,"欠食"))+COUNTIFS(食数記録!$A:$A,$A19,食数記録!$B:$B,"朝",食数記録!$F:$F,"男性GH",食数記録!$D:$D,"臨時喫食")+COUNTIFS(食数記録!$A:$A,$A19,食数記録!$B:$B,"朝",食数記録!$F:$F,"女性GH",食数記録!$D:$D,"臨時喫食")+SUMIFS(職員食来客記録!$C:$C,職員食来客記録!$A:$A,$A19,職員食来客記録!$B:$B,"朝")+SUMIFS(職員食来客記録!$D:$D,職員食来客記録!$A:$A,$A19,職員食来客記録!$B:$B,"朝")) -> 2 | D19: =IF($A19="","",(COUNTIFS(利用者名簿!$B:$B,"男性入所",利用者名簿!$G:$G,"在籍")-COUNTIFS(食数記録!$A:$A,$A19,食数記録!$B:$B,"昼",食数記録!$F:$F,"男性入所",食数記録!$D:$D,"欠食"))+(COUNTIFS(利用者名簿!$B:$B,"女性入所",利用者名簿!$G:$G,"在籍")-COUNTIFS(食数記録!$A:$A,$A19,食数記録!$B:$B,"昼",食数記録!$F:$F,"女性入所",食数記録!$D:$D,"欠食"))+(IF(WEEKDAY($A19,2)<=5,COUNTIFS(利用者名簿!$B:$B,"男性GH",利用者名簿!$G:$G,"在籍")-COUNTIFS(食数記録!$A:$A,$A19,食数記録!$B:$B,"昼",食数記録!$F:$F,"男性GH",食数記録!$D:$D,"欠食"),COUNTIFS(食数記録!$A:$A,$A19,食数記録!$B:$B,"昼",食数記録!$F:$F,"男性GH",食数記録!$D:$D,"臨時喫食")))+(IF(WEEKDAY($A19,2)<=5,COUNTIFS(利用者名簿!$B:$B,"女性GH",利用者名簿!$G:$G,"在籍")-COUNTIFS(食数記録!$A:$A,$A19,食数記録!$B:$B,"昼",食数記録!$F:$F,"女性GH",食数記録!$D:$D,"欠食"),COUNTIFS(食数記録!$A:$A,$A19,食数記録!$B:$B,"昼",食数記録!$F:$F,"女性GH",食数記録!$D:$D,"臨時喫食")))+SUMIFS(職員食来客記録!$C:$C,職員食来客記録!$A:$A,$A19,職員食来客記録!$B:$B,"昼")+SUMIFS(職員食来客記録!$D:$D,職員食来客記録!$A:$A,$A19,職員食来客記録!$B:$B,"昼")) -> 3 | E19: =IF($A19="","",(COUNTIFS(利用者名簿!$B:$B,"男性入所",利用者名簿!$G:$G,"在籍")-COUNTIFS(食数記録!$A:$A,$A19,食数記録!$B:$B,"夕",食数記録!$F:$F,"男性入所",食数記録!$D:$D,"欠食"))+(COUNTIFS(利用者名簿!$B:$B,"女性入所",利用者名簿!$G:$G,"在籍")-COUNTIFS(食数記録!$A:$A,$A19,食数記録!$B:$B,"夕",食数記録!$F:$F,"女性入所",食数記録!$D:$D,"欠食"))+COUNTIFS(食数記録!$A:$A,$A19,食数記録!$B:$B,"夕",食数記録!$F:$F,"男性GH",食数記録!$D:$D,"臨時喫食")+COUNTIFS(食数記録!$A:$A,$A19,食数記録!$B:$B,"夕",食数記録!$F:$F,"女性GH",食数記録!$D:$D,"臨時喫食")+SUMIFS(職員食来客記録!$C:$C,職員食来客記録!$A:$A,$A19,職員食来客記録!$B:$B,"夕")+SUMIFS(職員食来客記録!$D:$D,職員食来客記録!$A:$A,$A19,職員食来客記録!$B:$B,"夕")) -> 2
A20: =IF(MONTH($C$3+7)=MONTH($C$3),$C$3+7,"") -> 46242 | B20: =IF(A20="","",TEXT(A20,"aaa")) -> Sat | C20: =IF($A20="","",(COUNTIFS(利用者名簿!$B:$B,"男性入所",利用者名簿!$G:$G,"在籍")-COUNTIFS(食数記録!$A:$A,$A20,食数記録!$B:$B,"朝",食数記録!$F:$F,"男性入所",食数記録!$D:$D,"欠食"))+(COUNTIFS(利用者名簿!$B:$B,"女性入所",利用者名簿!$G:$G,"在籍")-COUNTIFS(食数記録!$A:$A,$A20,食数記録!$B:$B,"朝",食数記録!$F:$F,"女性入所",食数記録!$D:$D,"欠食"))+COUNTIFS(食数記録!$A:$A,$A20,食数記録!$B:$B,"朝",食数記録!$F:$F,"男性GH",食数記録!$D:$D,"臨時喫食")+COUNTIFS(食数記録!$A:$A,$A20,食数記録!$B:$B,"朝",食数記録!$F:$F,"女性GH",食数記録!$D:$D,"臨時喫食")+SUMIFS(職員食来客記録!$C:$C,職員食来客記録!$A:$A,$A20,職員食来客記録!$B:$B,"朝")+SUMIFS(職員食来客記録!$D:$D,職員食来客記録!$A:$A,$A20,職員食来客記録!$B:$B,"朝")) -> 2 | D20: =IF($A20="","",(COUNTIFS(利用者名簿!$B:$B,"男性入所",利用者名簿!$G:$G,"在籍")-COUNTIFS(食数記録!$A:$A,$A20,食数記録!$B:$B,"昼",食数記録!$F:$F,"男性入所",食数記録!$D:$D,"欠食"))+(COUNTIFS(利用者名簿!$B:$B,"女性入所",利用者名簿!$G:$G,"在籍")-COUNTIFS(食数記録!$A:$A,$A20,食数記録!$B:$B,"昼",食数記録!$F:$F,"女性入所",食数記録!$D:$D,"欠食"))+(IF(WEEKDAY($A20,2)<=5,COUNTIFS(利用者名簿!$B:$B,"男性GH",利用者名簿!$G:$G,"在籍")-COUNTIFS(食数記録!$A:$A,$A20,食数記録!$B:$B,"昼",食数記録!$F:$F,"男性GH",食数記録!$D:$D,"欠食"),COUNTIFS(食数記録!$A:$A,$A20,食数記録!$B:$B,"昼",食数記録!$F:$F,"男性GH",食数記録!$D:$D,"臨時喫食")))+(IF(WEEKDAY($A20,2)<=5,COUNTIFS(利用者名簿!$B:$B,"女性GH",利用者名簿!$G:$G,"在籍")-COUNTIFS(食数記録!$A:$A,$A20,食数記録!$B:$B,"昼",食数記録!$F:$F,"女性GH",食数記録!$D:$D,"欠食"),COUNTIFS(食数記録!$A:$A,$A20,食数記録!$B:$B,"昼",食数記録!$F:$F,"女性GH",食数記録!$D:$D,"臨時喫食")))+SUMIFS(職員食来客記録!$C:$C,職員食来客記録!$A:$A,$A20,職員食来客記録!$B:$B,"昼")+SUMIFS(職員食来客記録!$D:$D,職員食来客記録!$A:$A,$A20,職員食来客記録!$B:$B,"昼")) -> 2 | E20: =IF($A20="","",(COUNTIFS(利用者名簿!$B:$B,"男性入所",利用者名簿!$G:$G,"在籍")-COUNTIFS(食数記録!$A:$A,$A20,食数記録!$B:$B,"夕",食数記録!$F:$F,"男性入所",食数記録!$D:$D,"欠食"))+(COUNTIFS(利用者名簿!$B:$B,"女性入所",利用者名簿!$G:$G,"在籍")-COUNTIFS(食数記録!$A:$A,$A20,食数記録!$B:$B,"夕",食数記録!$F:$F,"女性入所",食数記録!$D:$D,"欠食"))+COUNTIFS(食数記録!$A:$A,$A20,食数記録!$B:$B,"夕",食数記録!$F:$F,"男性GH",食数記録!$D:$D,"臨時喫食")+COUNTIFS(食数記録!$A:$A,$A20,食数記録!$B:$B,"夕",食数記録!$F:$F,"女性GH",食数記録!$D:$D,"臨時喫食")+SUMIFS(職員食来客記録!$C:$C,職員食来客記録!$A:$A,$A20,職員食来客記録!$B:$B,"夕")+SUMIFS(職員食来客記録!$D:$D,職員食来客記録!$A:$A,$A20,職員食来客記録!$B:$B,"夕")) -> 2
A21: =IF(MONTH($C$3+8)=MONTH($C$3),$C$3+8,"") -> 46243 | B21: =IF(A21="","",TEXT(A21,"aaa")) -> Sun | C21: =IF($A21="","",(COUNTIFS(利用者名簿!$B:$B,"男性入所",利用者名簿!$G:$G,"在籍")-COUNTIFS(食数記録!$A:$A,$A21,食数記録!$B:$B,"朝",食数記録!$F:$F,"男性入所",食数記録!$D:$D,"欠食"))+(COUNTIFS(利用者名簿!$B:$B,"女性入所",利用者名簿!$G:$G,"在籍")-COUNTIFS(食数記録!$A:$A,$A21,食数記録!$B:$B,"朝",食数記録!$F:$F,"女性入所",食数記録!$D:$D,"欠食"))+COUNTIFS(食数記録!$A:$A,$A21,食数記録!$B:$B,"朝",食数記録!$F:$F,"男性GH",食数記録!$D:$D,"臨時喫食")+COUNTIFS(食数記録!$A:$A,$A21,食数記録!$B:$B,"朝",食数記録!$F:$F,"女性GH",食数記録!$D:$D,"臨時喫食")+SUMIFS(職員食来客記録!$C:$C,職員食来客記録!$A:$A,$A21,職員食来客記録!$B:$B,"朝")+SUMIFS(職員食来客記録!$D:$D,職員食来客記録!$A:$A,$A21,職員食来客記録!$B:$B,"朝")) -> 2 | D21: =IF($A21="","",(COUNTIFS(利用者名簿!$B:$B,"男性入所",利用者名簿!$G:$G,"在籍")-COUNTIFS(食数記録!$A:$A,$A21,食数記録!$B:$B,"昼",食数記録!$F:$F,"男性入所",食数記録!$D:$D,"欠食"))+(COUNTIFS(利用者名簿!$B:$B,"女性入所",利用者名簿!$G:$G,"在籍")-COUNTIFS(食数記録!$A:$A,$A21,食数記録!$B:$B,"昼",食数記録!$F:$F,"女性入所",食数記録!$D:$D,"欠食"))+(IF(WEEKDAY($A21,2)<=5,COUNTIFS(利用者名簿!$B:$B,"男性GH",利用者名簿!$G:$G,"在籍")-COUNTIFS(食数記録!$A:$A,$A21,食数記録!$B:$B,"昼",食数記録!$F:$F,"男性GH",食数記録!$D:$D,"欠食"),COUNTIFS(食数記録!$A:$A,$A21,食数記録!$B:$B,"昼",食数記録!$F:$F,"男性GH",食数記録!$D:$D,"臨時喫食")))+(IF(WEEKDAY($A21,2)<=5,COUNTIFS(利用者名簿!$B:$B,"女性GH",利用者名簿!$G:$G,"在籍")-COUNTIFS(食数記録!$A:$A,$A21,食数記録!$B:$B,"昼",食数記録!$F:$F,"女性GH",食数記録!$D:$D,"欠食"),COUNTIFS(食数記録!$A:$A,$A21,食数記録!$B:$B,"昼",食数記録!$F:$F,"女性GH",食数記録!$D:$D,"臨時喫食")))+SUMIFS(職員食来客記録!$C:$C,職員食来客記録!$A:$A,$A21,職員食来客記録!$B:$B,"昼")+SUMIFS(職員食来客記録!$D:$D,職員食来客記録!$A:$A,$A21,職員食来客記録!$B:$B,"昼")) -> 2 | E21: =IF($A21="","",(COUNTIFS(利用者名簿!$B:$B,"男性入所",利用者名簿!$G:$G,"在籍")-COUNTIFS(食数記録!$A:$A,$A21,食数記録!$B:$B,"夕",食数記録!$F:$F,"男性入所",食数記録!$D:$D,"欠食"))+(COUNTIFS(利用者名簿!$B:$B,"女性入所",利用者名簿!$G:$G,"在籍")-COUNTIFS(食数記録!$A:$A,$A21,食数記録!$B:$B,"夕",食数記録!$F:$F,"女性入所",食数記録!$D:$D,"欠食"))+COUNTIFS(食数記録!$A:$A,$A21,食数記録!$B:$B,"夕",食数記録!$F:$F,"男性GH",食数記録!$D:$D,"臨時喫食")+COUNTIFS(食数記録!$A:$A,$A21,食数記録!$B:$B,"夕",食数記録!$F:$F,"女性GH",食数記録!$D:$D,"臨時喫食")+SUMIFS(職員食来客記録!$C:$C,職員食来客記録!$A:$A,$A21,職員食来客記録!$B:$B,"夕")+SUMIFS(職員食来客記録!$D:$D,職員食来客記録!$A:$A,$A21,職員食来客記録!$B:$B,"夕")) -> 2
A22: =IF(MONTH($C$3+9)=MONTH($C$3),$C$3+9,"") -> 46244 | B22: =IF(A22="","",TEXT(A22,"aaa")) -> Mon | C22: =IF($A22="","",(COUNTIFS(利用者名簿!$B:$B,"男性入所",利用者名簿!$G:$G,"在籍")-COUNTIFS(食数記録!$A:$A,$A22,食数記録!$B:$B,"朝",食数記録!$F:$F,"男性入所",食数記録!$D:$D,"欠食"))+(COUNTIFS(利用者名簿!$B:$B,"女性入所",利用者名簿!$G:$G,"在籍")-COUNTIFS(食数記録!$A:$A,$A22,食数記録!$B:$B,"朝",食数記録!$F:$F,"女性入所",食数記録!$D:$D,"欠食"))+COUNTIFS(食数記録!$A:$A,$A22,食数記録!$B:$B,"朝",食数記録!$F:$F,"男性GH",食数記録!$D:$D,"臨時喫食")+COUNTIFS(食数記録!$A:$A,$A22,食数記録!$B:$B,"朝",食数記録!$F:$F,"女性GH",食数記録!$D:$D,"臨時喫食")+SUMIFS(職員食来客記録!$C:$C,職員食来客記録!$A:$A,$A22,職員食来客記録!$B:$B,"朝")+SUMIFS(職員食来客記録!$D:$D,職員食来客記録!$A:$A,$A22,職員食来客記録!$B:$B,"朝")) -> 2 | D22: =IF($A22="","",(COUNTIFS(利用者名簿!$B:$B,"男性入所",利用者名簿!$G:$G,"在籍")-COUNTIFS(食数記録!$A:$A,$A22,食数記録!$B:$B,"昼",食数記録!$F:$F,"男性入所",食数記録!$D:$D,"欠食"))+(COUNTIFS(利用者名簿!$B:$B,"女性入所",利用者名簿!$G:$G,"在籍")-COUNTIFS(食数記録!$A:$A,$A22,食数記録!$B:$B,"昼",食数記録!$F:$F,"女性入所",食数記録!$D:$D,"欠食"))+(IF(WEEKDAY($A22,2)<=5,COUNTIFS(利用者名簿!$B:$B,"男性GH",利用者名簿!$G:$G,"在籍")-COUNTIFS(食数記録!$A:$A,$A22,食数記録!$B:$B,"昼",食数記録!$F:$F,"男性GH",食数記録!$D:$D,"欠食"),COUNTIFS(食数記録!$A:$A,$A22,食数記録!$B:$B,"昼",食数記録!$F:$F,"男性GH",食数記録!$D:$D,"臨時喫食")))+(IF(WEEKDAY($A22,2)<=5,COUNTIFS(利用者名簿!$B:$B,"女性GH",利用者名簿!$G:$G,"在籍")-COUNTIFS(食数記録!$A:$A,$A22,食数記録!$B:$B,"昼",食数記録!$F:$F,"女性GH",食数記録!$D:$D,"欠食"),COUNTIFS(食数記録!$A:$A,$A22,食数記録!$B:$B,"昼",食数記録!$F:$F,"女性GH",食数記録!$D:$D,"臨時喫食")))+SUMIFS(職員食来客記録!$C:$C,職員食来客記録!$A:$A,$A22,職員食来客記録!$B:$B,"昼")+SUMIFS(職員食来客記録!$D:$D,職員食来客記録!$A:$A,$A22,職員食来客記録!$B:$B,"昼")) -> 3 | E22: =IF($A22="","",(COUNTIFS(利用者名簿!$B:$B,"男性入所",利用者名簿!$G:$G,"在籍")-COUNTIFS(食数記録!$A:$A,$A22,食数記録!$B:$B,"夕",食数記録!$F:$F,"男性入所",食数記録!$D:$D,"欠食"))+(COUNTIFS(利用者名簿!$B:$B,"女性入所",利用者名簿!$G:$G,"在籍")-COUNTIFS(食数記録!$A:$A,$A22,食数記録!$B:$B,"夕",食数記録!$F:$F,"女性入所",食数記録!$D:$D,"欠食"))+COUNTIFS(食数記録!$A:$A,$A22,食数記録!$B:$B,"夕",食数記録!$F:$F,"男性GH",食数記録!$D:$D,"臨時喫食")+COUNTIFS(食数記録!$A:$A,$A22,食数記録!$B:$B,"夕",食数記録!$F:$F,"女性GH",食数記録!$D:$D,"臨時喫食")+SUMIFS(職員食来客記録!$C:$C,職員食来客記録!$A:$A,$A22,職員食来客記録!$B:$B,"夕")+SUMIFS(職員食来客記録!$D:$D,職員食来客記録!$A:$A,$A22,職員食来客記録!$B:$B,"夕")) -> 2
A23: =IF(MONTH($C$3+10)=MONTH($C$3),$C$3+10,"") -> 46245 | B23: =IF(A23="","",TEXT(A23,"aaa")) -> Tue | C23: =IF($A23="","",(COUNTIFS(利用者名簿!$B:$B,"男性入所",利用者名簿!$G:$G,"在籍")-COUNTIFS(食数記録!$A:$A,$A23,食数記録!$B:$B,"朝",食数記録!$F:$F,"男性入所",食数記録!$D:$D,"欠食"))+(COUNTIFS(利用者名簿!$B:$B,"女性入所",利用者名簿!$G:$G,"在籍")-COUNTIFS(食数記録!$A:$A,$A23,食数記録!$B:$B,"朝",食数記録!$F:$F,"女性入所",食数記録!$D:$D,"欠食"))+COUNTIFS(食数記録!$A:$A,$A23,食数記録!$B:$B,"朝",食数記録!$F:$F,"男性GH",食数記録!$D:$D,"臨時喫食")+COUNTIFS(食数記録!$A:$A,$A23,食数記録!$B:$B,"朝",食数記録!$F:$F,"女性GH",食数記録!$D:$D,"臨時喫食")+SUMIFS(職員食来客記録!$C:$C,職員食来客記録!$A:$A,$A23,職員食来客記録!$B:$B,"朝")+SUMIFS(職員食来客記録!$D:$D,職員食来客記録!$A:$A,$A23,職員食来客記録!$B:$B,"朝")) -> 2 | D23: =IF($A23="","",(COUNTIFS(利用者名簿!$B:$B,"男性入所",利用者名簿!$G:$G,"在籍")-COUNTIFS(食数記録!$A:$A,$A23,食数記録!$B:$B,"昼",食数記録!$F:$F,"男性入所",食数記録!$D:$D,"欠食"))+(COUNTIFS(利用者名簿!$B:$B,"女性入所",利用者名簿!$G:$G,"在籍")-COUNTIFS(食数記録!$A:$A,$A23,食数記録!$B:$B,"昼",食数記録!$F:$F,"女性入所",食数記録!$D:$D,"欠食"))+(IF(WEEKDAY($A23,2)<=5,COUNTIFS(利用者名簿!$B:$B,"男性GH",利用者名簿!$G:$G,"在籍")-COUNTIFS(食数記録!$A:$A,$A23,食数記録!$B:$B,"昼",食数記録!$F:$F,"男性GH",食数記録!$D:$D,"欠食"),COUNTIFS(食数記録!$A:$A,$A23,食数記録!$B:$B,"昼",食数記録!$F:$F,"男性GH",食数記録!$D:$D,"臨時喫食")))+(IF(WEEKDAY($A23,2)<=5,COUNTIFS(利用者名簿!$B:$B,"女性GH",利用者名簿!$G:$G,"在籍")-COUNTIFS(食数記録!$A:$A,$A23,食数記録!$B:$B,"昼",食数記録!$F:$F,"女性GH",食数記録!$D:$D,"欠食"),COUNTIFS(食数記録!$A:$A,$A23,食数記録!$B:$B,"昼",食数記録!$F:$F,"女性GH",食数記録!$D:$D,"臨時喫食")))+SUMIFS(職員食来客記録!$C:$C,職員食来客記録!$A:$A,$A23,職員食来客記録!$B:$B,"昼")+SUMIFS(職員食来客記録!$D:$D,職員食来客記録!$A:$A,$A23,職員食来客記録!$B:$B,"昼")) -> 3 | E23: =IF($A23="","",(COUNTIFS(利用者名簿!$B:$B,"男性入所",利用者名簿!$G:$G,"在籍")-COUNTIFS(食数記録!$A:$A,$A23,食数記録!$B:$B,"夕",食数記録!$F:$F,"男性入所",食数記録!$D:$D,"欠食"))+(COUNTIFS(利用者名簿!$B:$B,"女性入所",利用者名簿!$G:$G,"在籍")-COUNTIFS(食数記録!$A:$A,$A23,食数記録!$B:$B,"夕",食数記録!$F:$F,"女性入所",食数記録!$D:$D,"欠食"))+COUNTIFS(食数記録!$A:$A,$A23,食数記録!$B:$B,"夕",食数記録!$F:$F,"男性GH",食数記録!$D:$D,"臨時喫食")+COUNTIFS(食数記録!$A:$A,$A23,食数記録!$B:$B,"夕",食数記録!$F:$F,"女性GH",食数記録!$D:$D,"臨時喫食")+SUMIFS(職員食来客記録!$C:$C,職員食来客記録!$A:$A,$A23,職員食来客記録!$B:$B,"夕")+SUMIFS(職員食来客記録!$D:$D,職員食来客記録!$A:$A,$A23,職員食来客記録!$B:$B,"夕")) -> 2
A24: =IF(MONTH($C$3+11)=MONTH($C$3),$C$3+11,"") -> 46246 | B24: =IF(A24="","",TEXT(A24,"aaa")) -> Wed | C24: =IF($A24="","",(COUNTIFS(利用者名簿!$B:$B,"男性入所",利用者名簿!$G:$G,"在籍")-COUNTIFS(食数記録!$A:$A,$A24,食数記録!$B:$B,"朝",食数記録!$F:$F,"男性入所",食数記録!$D:$D,"欠食"))+(COUNTIFS(利用者名簿!$B:$B,"女性入所",利用者名簿!$G:$G,"在籍")-COUNTIFS(食数記録!$A:$A,$A24,食数記録!$B:$B,"朝",食数記録!$F:$F,"女性入所",食数記録!$D:$D,"欠食"))+COUNTIFS(食数記録!$A:$A,$A24,食数記録!$B:$B,"朝",食数記録!$F:$F,"男性GH",食数記録!$D:$D,"臨時喫食")+COUNTIFS(食数記録!$A:$A,$A24,食数記録!$B:$B,"朝",食数記録!$F:$F,"女性GH",食数記録!$D:$D,"臨時喫食")+SUMIFS(職員食来客記録!$C:$C,職員食来客記録!$A:$A,$A24,職員食来客記録!$B:$B,"朝")+SUMIFS(職員食来客記録!$D:$D,職員食来客記録!$A:$A,$A24,職員食来客記録!$B:$B,"朝")) -> 2 | D24: =IF($A24="","",(COUNTIFS(利用者名簿!$B:$B,"男性入所",利用者名簿!$G:$G,"在籍")-COUNTIFS(食数記録!$A:$A,$A24,食数記録!$B:$B,"昼",食数記録!$F:$F,"男性入所",食数記録!$D:$D,"欠食"))+(COUNTIFS(利用者名簿!$B:$B,"女性入所",利用者名簿!$G:$G,"在籍")-COUNTIFS(食数記録!$A:$A,$A24,食数記録!$B:$B,"昼",食数記録!$F:$F,"女性入所",食数記録!$D:$D,"欠食"))+(IF(WEEKDAY($A24,2)<=5,COUNTIFS(利用者名簿!$B:$B,"男性GH",利用者名簿!$G:$G,"在籍")-COUNTIFS(食数記録!$A:$A,$A24,食数記録!$B:$B,"昼",食数記録!$F:$F,"男性GH",食数記録!$D:$D,"欠食"),COUNTIFS(食数記録!$A:$A,$A24,食数記録!$B:$B,"昼",食数記録!$F:$F,"男性GH",食数記録!$D:$D,"臨時喫食")))+(IF(WEEKDAY($A24,2)<=5,COUNTIFS(利用者名簿!$B:$B,"女性GH",利用者名簿!$G:$G,"在籍")-COUNTIFS(食数記録!$A:$A,$A24,食数記録!$B:$B,"昼",食数記録!$F:$F,"女性GH",食数記録!$D:$D,"欠食"),COUNTIFS(食数記録!$A:$A,$A24,食数記録!$B:$B,"昼",食数記録!$F:$F,"女性GH",食数記録!$D:$D,"臨時喫食")))+SUMIFS(職員食来客記録!$C:$C,職員食来客記録!$A:$A,$A24,職員食来客記録!$B:$B,"昼")+SUMIFS(職員食来客記録!$D:$D,職員食来客記録!$A:$A,$A24,職員食来客記録!$B:$B,"昼")) -> 3 | E24: =IF($A24="","",(COUNTIFS(利用者名簿!$B:$B,"男性入所",利用者名簿!$G:$G,"在籍")-COUNTIFS(食数記録!$A:$A,$A24,食数記録!$B:$B,"夕",食数記録!$F:$F,"男性入所",食数記録!$D:$D,"欠食"))+(COUNTIFS(利用者名簿!$B:$B,"女性入所",利用者名簿!$G:$G,"在籍")-COUNTIFS(食数記録!$A:$A,$A24,食数記録!$B:$B,"夕",食数記録!$F:$F,"女性入所",食数記録!$D:$D,"欠食"))+COUNTIFS(食数記録!$A:$A,$A24,食数記録!$B:$B,"夕",食数記録!$F:$F,"男性GH",食数記録!$D:$D,"臨時喫食")+COUNTIFS(食数記録!$A:$A,$A24,食数記録!$B:$B,"夕",食数記録!$F:$F,"女性GH",食数記録!$D:$D,"臨時喫食")+SUMIFS(職員食来客記録!$C:$C,職員食来客記録!$A:$A,$A24,職員食来客記録!$B:$B,"夕")+SUMIFS(職員食来客記録!$D:$D,職員食来客記録!$A:$A,$A24,職員食来客記録!$B:$B,"夕")) -> 2
A25: =IF(MONTH($C$3+12)=MONTH($C$3),$C$3+12,"") -> 46247 | B25: =IF(A25="","",TEXT(A25,"aaa")) -> Thu | C25: =IF($A25="","",(COUNTIFS(利用者名簿!$B:$B,"男性入所",利用者名簿!$G:$G,"在籍")-COUNTIFS(食数記録!$A:$A,$A25,食数記録!$B:$B,"朝",食数記録!$F:$F,"男性入所",食数記録!$D:$D,"欠食"))+(COUNTIFS(利用者名簿!$B:$B,"女性入所",利用者名簿!$G:$G,"在籍")-COUNTIFS(食数記録!$A:$A,$A25,食数記録!$B:$B,"朝",食数記録!$F:$F,"女性入所",食数記録!$D:$D,"欠食"))+COUNTIFS(食数記録!$A:$A,$A25,食数記録!$B:$B,"朝",食数記録!$F:$F,"男性GH",食数記録!$D:$D,"臨時喫食")+COUNTIFS(食数記録!$A:$A,$A25,食数記録!$B:$B,"朝",食数記録!$F:$F,"女性GH",食数記録!$D:$D,"臨時喫食")+SUMIFS(職員食来客記録!$C:$C,職員食来客記録!$A:$A,$A25,職員食来客記録!$B:$B,"朝")+SUMIFS(職員食来客記録!$D:$D,職員食来客記録!$A:$A,$A25,職員食来客記録!$B:$B,"朝")) -> 1 | D25: =IF($A25="","",(COUNTIFS(利用者名簿!$B:$B,"男性入所",利用者名簿!$G:$G,"在籍")-COUNTIFS(食数記録!$A:$A,$A25,食数記録!$B:$B,"昼",食数記録!$F:$F,"男性入所",食数記録!$D:$D,"欠食"))+(COUNTIFS(利用者名簿!$B:$B,"女性入所",利用者名簿!$G:$G,"在籍")-COUNTIFS(食数記録!$A:$A,$A25,食数記録!$B:$B,"昼",食数記録!$F:$F,"女性入所",食数記録!$D:$D,"欠食"))+(IF(WEEKDAY($A25,2)<=5,COUNTIFS(利用者名簿!$B:$B,"男性GH",利用者名簿!$G:$G,"在籍")-COUNTIFS(食数記録!$A:$A,$A25,食数記録!$B:$B,"昼",食数記録!$F:$F,"男性GH",食数記録!$D:$D,"欠食"),COUNTIFS(食数記録!$A:$A,$A25,食数記録!$B:$B,"昼",食数記録!$F:$F,"男性GH",食数記録!$D:$D,"臨時喫食")))+(IF(WEEKDAY($A25,2)<=5,COUNTIFS(利用者名簿!$B:$B,"女性GH",利用者名簿!$G:$G,"在籍")-COUNTIFS(食数記録!$A:$A,$A25,食数記録!$B:$B,"昼",食数記録!$F:$F,"女性GH",食数記録!$D:$D,"欠食"),COUNTIFS(食数記録!$A:$A,$A25,食数記録!$B:$B,"昼",食数記録!$F:$F,"女性GH",食数記録!$D:$D,"臨時喫食")))+SUMIFS(職員食来客記録!$C:$C,職員食来客記録!$A:$A,$A25,職員食来客記録!$B:$B,"昼")+SUMIFS(職員食来客記録!$D:$D,職員食来客記録!$A:$A,$A25,職員食来客記録!$B:$B,"昼")) -> 4 | E25: =IF($A25="","",(COUNTIFS(利用者名簿!$B:$B,"男性入所",利用者名簿!$G:$G,"在籍")-COUNTIFS(食数記録!$A:$A,$A25,食数記録!$B:$B,"夕",食数記録!$F:$F,"男性入所",食数記録!$D:$D,"欠食"))+(COUNTIFS(利用者名簿!$B:$B,"女性入所",利用者名簿!$G:$G,"在籍")-COUNTIFS(食数記録!$A:$A,$A25,食数記録!$B:$B,"夕",食数記録!$F:$F,"女性入所",食数記録!$D:$D,"欠食"))+COUNTIFS(食数記録!$A:$A,$A25,食数記録!$B:$B,"夕",食数記録!$F:$F,"男性GH",食数記録!$D:$D,"臨時喫食")+COUNTIFS(食数記録!$A:$A,$A25,食数記録!$B:$B,"夕",食数記録!$F:$F,"女性GH",食数記録!$D:$D,"臨時喫食")+SUMIFS(職員食来客記録!$C:$C,職員食来客記録!$A:$A,$A25,職員食来客記録!$B:$B,"夕")+SUMIFS(職員食来客記録!$D:$D,職員食来客記録!$A:$A,$A25,職員食来客記録!$B:$B,"夕")) -> 2
A26: =IF(MONTH($C$3+13)=MONTH($C$3),$C$3+13,"") -> 46248 | B26: =IF(A26="","",TEXT(A26,"aaa")) -> Fri | C26: =IF($A26="","",(COUNTIFS(利用者名簿!$B:$B,"男性入所",利用者名簿!$G:$G,"在籍")-COUNTIFS(食数記録!$A:$A,$A26,食数記録!$B:$B,"朝",食数記録!$F:$F,"男性入所",食数記録!$D:$D,"欠食"))+(COUNTIFS(利用者名簿!$B:$B,"女性入所",利用者名簿!$G:$G,"在籍")-COUNTIFS(食数記録!$A:$A,$A26,食数記録!$B:$B,"朝",食数記録!$F:$F,"女性入所",食数記録!$D:$D,"欠食"))+COUNTIFS(食数記録!$A:$A,$A26,食数記録!$B:$B,"朝",食数記録!$F:$F,"男性GH",食数記録!$D:$D,"臨時喫食")+COUNTIFS(食数記録!$A:$A,$A26,食数記録!$B:$B,"朝",食数記録!$F:$F,"女性GH",食数記録!$D:$D,"臨時喫食")+SUMIFS(職員食来客記録!$C:$C,職員食来客記録!$A:$A,$A26,職員食来客記録!$B:$B,"朝")+SUMIFS(職員食来客記録!$D:$D,職員食来客記録!$A:$A,$A26,職員食来客記録!$B:$B,"朝")) -> 2 | D26: =IF($A26="","",(COUNTIFS(利用者名簿!$B:$B,"男性入所",利用者名簿!$G:$G,"在籍")-COUNTIFS(食数記録!$A:$A,$A26,食数記録!$B:$B,"昼",食数記録!$F:$F,"男性入所",食数記録!$D:$D,"欠食"))+(COUNTIFS(利用者名簿!$B:$B,"女性入所",利用者名簿!$G:$G,"在籍")-COUNTIFS(食数記録!$A:$A,$A26,食数記録!$B:$B,"昼",食数記録!$F:$F,"女性入所",食数記録!$D:$D,"欠食"))+(IF(WEEKDAY($A26,2)<=5,COUNTIFS(利用者名簿!$B:$B,"男性GH",利用者名簿!$G:$G,"在籍")-COUNTIFS(食数記録!$A:$A,$A26,食数記録!$B:$B,"昼",食数記録!$F:$F,"男性GH",食数記録!$D:$D,"欠食"),COUNTIFS(食数記録!$A:$A,$A26,食数記録!$B:$B,"昼",食数記録!$F:$F,"男性GH",食数記録!$D:$D,"臨時喫食")))+(IF(WEEKDAY($A26,2)<=5,COUNTIFS(利用者名簿!$B:$B,"女性GH",利用者名簿!$G:$G,"在籍")-COUNTIFS(食数記録!$A:$A,$A26,食数記録!$B:$B,"昼",食数記録!$F:$F,"女性GH",食数記録!$D:$D,"欠食"),COUNTIFS(食数記録!$A:$A,$A26,食数記録!$B:$B,"昼",食数記録!$F:$F,"女性GH",食数記録!$D:$D,"臨時喫食")))+SUMIFS(職員食来客記録!$C:$C,職員食来客記録!$A:$A,$A26,職員食来客記録!$B:$B,"昼")+SUMIFS(職員食来客記録!$D:$D,職員食来客記録!$A:$A,$A26,職員食来客記録!$B:$B,"昼")) -> 3 | E26: =IF($A26="","",(COUNTIFS(利用者名簿!$B:$B,"男性入所",利用者名簿!$G:$G,"在籍")-COUNTIFS(食数記録!$A:$A,$A26,食数記録!$B:$B,"夕",食数記録!$F:$F,"男性入所",食数記録!$D:$D,"欠食"))+(COUNTIFS(利用者名簿!$B:$B,"女性入所",利用者名簿!$G:$G,"在籍")-COUNTIFS(食数記録!$A:$A,$A26,食数記録!$B:$B,"夕",食数記録!$F:$F,"女性入所",食数記録!$D:$D,"欠食"))+COUNTIFS(食数記録!$A:$A,$A26,食数記録!$B:$B,"夕",食数記録!$F:$F,"男性GH",食数記録!$D:$D,"臨時喫食")+COUNTIFS(食数記録!$A:$A,$A26,食数記録!$B:$B,"夕",食数記録!$F:$F,"女性GH",食数記録!$D:$D,"臨時喫食")+SUMIFS(職員食来客記録!$C:$C,職員食来客記録!$A:$A,$A26,職員食来客記録!$B:$B,"夕")+SUMIFS(職員食来客記録!$D:$D,職員食来客記録!$A:$A,$A26,職員食来客記録!$B:$B,"夕")) -> 2
A27: =IF(MONTH($C$3+14)=MONTH($C$3),$C$3+14,"") -> 46249 | B27: =IF(A27="","",TEXT(A27,"aaa")) -> Sat | C27: =IF($A27="","",(COUNTIFS(利用者名簿!$B:$B,"男性入所",利用者名簿!$G:$G,"在籍")-COUNTIFS(食数記録!$A:$A,$A27,食数記録!$B:$B,"朝",食数記録!$F:$F,"男性入所",食数記録!$D:$D,"欠食"))+(COUNTIFS(利用者名簿!$B:$B,"女性入所",利用者名簿!$G:$G,"在籍")-COUNTIFS(食数記録!$A:$A,$A27,食数記録!$B:$B,"朝",食数記録!$F:$F,"女性入所",食数記録!$D:$D,"欠食"))+COUNTIFS(食数記録!$A:$A,$A27,食数記録!$B:$B,"朝",食数記録!$F:$F,"男性GH",食数記録!$D:$D,"臨時喫食")+COUNTIFS(食数記録!$A:$A,$A27,食数記録!$B:$B,"朝",食数記録!$F:$F,"女性GH",食数記録!$D:$D,"臨時喫食")+SUMIFS(職員食来客記録!$C:$C,職員食来客記録!$A:$A,$A27,職員食来客記録!$B:$B,"朝")+SUMIFS(職員食来客記録!$D:$D,職員食来客記録!$A:$A,$A27,職員食来客記録!$B:$B,"朝")) -> 2 | D27: =IF($A27="","",(COUNTIFS(利用者名簿!$B:$B,"男性入所",利用者名簿!$G:$G,"在籍")-COUNTIFS(食数記録!$A:$A,$A27,食数記録!$B:$B,"昼",食数記録!$F:$F,"男性入所",食数記録!$D:$D,"欠食"))+(COUNTIFS(利用者名簿!$B:$B,"女性入所",利用者名簿!$G:$G,"在籍")-COUNTIFS(食数記録!$A:$A,$A27,食数記録!$B:$B,"昼",食数記録!$F:$F,"女性入所",食数記録!$D:$D,"欠食"))+(IF(WEEKDAY($A27,2)<=5,COUNTIFS(利用者名簿!$B:$B,"男性GH",利用者名簿!$G:$G,"在籍")-COUNTIFS(食数記録!$A:$A,$A27,食数記録!$B:$B,"昼",食数記録!$F:$F,"男性GH",食数記録!$D:$D,"欠食"),COUNTIFS(食数記録!$A:$A,$A27,食数記録!$B:$B,"昼",食数記録!$F:$F,"男性GH",食数記録!$D:$D,"臨時喫食")))+(IF(WEEKDAY($A27,2)<=5,COUNTIFS(利用者名簿!$B:$B,"女性GH",利用者名簿!$G:$G,"在籍")-COUNTIFS(食数記録!$A:$A,$A27,食数記録!$B:$B,"昼",食数記録!$F:$F,"女性GH",食数記録!$D:$D,"欠食"),COUNTIFS(食数記録!$A:$A,$A27,食数記録!$B:$B,"昼",食数記録!$F:$F,"女性GH",食数記録!$D:$D,"臨時喫食")))+SUMIFS(職員食来客記録!$C:$C,職員食来客記録!$A:$A,$A27,職員食来客記録!$B:$B,"昼")+SUMIFS(職員食来客記録!$D:$D,職員食来客記録!$A:$A,$A27,職員食来客記録!$B:$B,"昼")) -> 2 | E27: =IF($A27="","",(COUNTIFS(利用者名簿!$B:$B,"男性入所",利用者名簿!$G:$G,"在籍")-COUNTIFS(食数記録!$A:$A,$A27,食数記録!$B:$B,"夕",食数記録!$F:$F,"男性入所",食数記録!$D:$D,"欠食"))+(COUNTIFS(利用者名簿!$B:$B,"女性入所",利用者名簿!$G:$G,"在籍")-COUNTIFS(食数記録!$A:$A,$A27,食数記録!$B:$B,"夕",食数記録!$F:$F,"女性入所",食数記録!$D:$D,"欠食"))+COUNTIFS(食数記録!$A:$A,$A27,食数記録!$B:$B,"夕",食数記録!$F:$F,"男性GH",食数記録!$D:$D,"臨時喫食")+COUNTIFS(食数記録!$A:$A,$A27,食数記録!$B:$B,"夕",食数記録!$F:$F,"女性GH",食数記録!$D:$D,"臨時喫食")+SUMIFS(職員食来客記録!$C:$C,職員食来客記録!$A:$A,$A27,職員食来客記録!$B:$B,"夕")+SUMIFS(職員食来客記録!$D:$D,職員食来客記録!$A:$A,$A27,職員食来客記録!$B:$B,"夕")) -> 2
